Workbook
Name L_ActivityStatus: Lists!$B$5:$B$11
Name L_Owners: Lists!$E$5:$E$34
Name L_Qual: Lists!$C$5:$C$10
Name L_Rating: Lists!$D$5:$D$8
Name L_Types: Lists!$F$5:$F$18
Name L_VendorStatus: Lists!$A$5:$A$13
Name P_Names: Projects!$B$5:$B$54
Name V_Names: Vendors!$B$5:$B$400

Sheet Read Me
A1: RFI Tracker
A2: Agentic Procurement | Internal - do not share vendor data outside Agentic | Owner: Jason Knedlhans
A4: Version | B4: 1.0
A5: Version date | B5: 46300
A6: Live file | B6: RFI-Tracker.xlsx in the Procurement SharePoint library (AI Procurement > artifacts > rfi-tracker). Always open it from SharePoint; do not keep local copies.
A7: Status | B7: In review
A9: PURPOSE
A10: What | B10: One file for every RFI activity. Each RFI activity is its own tab, tied to one project and one vendor type, and lists the invited vendors with contacts, RFI status, last contact, qualification status, key item responses and ratings, and the next action, owner and date.
A12: TABS
A13: Dashboard | B13: Live totals by vendor type and by project.
A14: RFI Register | B14: Index of all RFI activities. Type the RFI ID; the rest fills from that tab.
A15: RFI-001 | B15: Example RFI (BESS vendors, placeholder project). Repurpose it for the first real RFI or delete it and its Register row.
A16: RFI_TEMPLATE | B16: Blank RFI tab. Copy it for each new RFI activity; never type data into the template itself.
A17: Vendors | B17: Master vendor and contact list. RFI tabs pull contacts from here, so update contacts here only.
A18: Key Items | B18: Default 5-7 key items per vendor type (10 slots). Drives the key item headers on RFI tabs.
A19: Projects | B19: Project list for the Project dropdown. Rename the placeholders.
A20: Lists | B20: Dropdown values (statuses, ratings, owners).
A21: Change Log | B21: Record of structural changes and new RFI tabs.
A23: ADD A NEW RFI ACTIVITY
A24: 1. Copy the template | B24: Right-click the RFI_TEMPLATE tab > Move or Copy > tick Create a copy > OK. (Excel for the web: right-click > Duplicate.)
A25: 2. Rename the tab | B25: Use the next RFI ID, e.g. RFI-002. Keep it short, no spaces.
A26: 3. Fill the header | B26: C3 RFI ID (same as tab name), C4 Project, C5 Vendor Type, title, owner, dates, status. Key item headers fill automatically from the vendor type.
A27: 4. Add vendors | B27: Pick vendors in column A (dropdown from the Vendors tab). Add a missing vendor to the Vendors tab first.
A28: 5. Register it | B28: Type the RFI ID in the next empty row of the RFI Register, then add a Change Log line.
A30: KEY ITEMS
A31: Change a header | B31: For this RFI only: type over the header in row 13 of the RFI tab. For all RFIs of a vendor type: edit the Key Items tab.
A32: Add a key item | B32: Type a name into a spare slot (shown as 'spare - type a name'), either on the RFI tab or on the Key Items tab.
A33: Rating | B33: Meets / Review / Risk / Fails / Not Rated. Fails and Review / Risk roll up to the tab summary, Register and Dashboard.
A35: CELL COLORS
A36: Yellow | B36: Enter or edit data.
A37: Grey | B37: Formula. Do not overwrite (exception: key item headers in row 13).
A38: Red / amber | B38: Overdue actions, Fails ratings, or a Register row whose tab name does not match.
A40: VERSION CONTROL
A41: Live file | B41: One file, one name, one link. Everyone edits the SharePoint copy in place (co-authoring with AutoSave on). Do not download, edit offline and re-upload, and do not Save As a new name.
A42: Version history | B42: SharePoint keeps every saved version automatically. To see or restore: File > Info > Version History (desktop) or the file's ... menu > Version history (SharePoint).
A43: Version number | B43: Major (2.0): structural change - new or removed columns, tabs other than new RFI tabs, formula changes. Minor (1.1): list or key item default changes, new RFI tab. Update the Version cell above and add a Change Log line for both.
A44: Snapshots | B44: Before a major version, save a dated copy to artifacts/archive/rfi-tracker/ (e.g. 2026-10-05_rfi-tracker_v1.0.xlsx).
A45: Data entry | B45: Routine updates (statuses, dates, responses) need no Change Log line; version history records them.
A47: DATA NOTES / RISKS
A48: Vendor data | B48: Vendors tab seeded 2026-10-05 from the vendor landscape tracker. It is AI-seeded from public sources and unverified; no named contacts yet. Mark Data Verified? = Yes once confirmed with the vendor.
...

Sheet Dashboard
A1: Dashboard
A2: Live totals from the RFI Register. Closed and cancelled RFIs are excluded from Active RFIs.
A4: Active RFIs | B4: Total RFIs | C4: Vendors invited | D4: RFIs sent | E4: Responses | F4: Actions overdue | G4: Key item fails
A5: =COUNTIFS('RFI Register'!$A$5:$A$104,"<>",'RFI Register'!$H$5:$H$104,"<>Closed*",'RFI Register'!$H$5:$H$104,"<>Cancelled") -> 1 | B5: =COUNTA('RFI Register'!$A$5:$A$104) -> 1 | C5: =SUM('RFI Register'!$I$5:$I$104) -> 10 | D5: =SUM('RFI Register'!$J$5:$J$104) -> 0 | E5: =SUM('RFI Register'!$K$5:$K$104) -> 0 | F5: =SUM('RFI Register'!$L$5:$L$104) -> 0 | G5: =SUM('RFI Register'!$M$5:$M$104) -> 0
A7: By vendor type
A8: Vendor Type | B8: RFIs | C8: Active | D8: Vendors Invited | E8: Responses | F8: Actions Overdue | G8: Key Item Fails
A9: Environmental Engineering | B9: =IF($A9="","",COUNTIF('RFI Register'!$C$5:$C$104,$A9)) -> 0 | C9: =IF($A9="","",COUNTIFS('RFI Register'!$C$5:$C$104,$A9,'RFI Register'!$H$5:$H$104,"<>Closed*",'RFI Register'!$H$5:$H$104,"<>Cancelled")) -> 0 | D9: =IF($A9="","",SUMIF('RFI Register'!$C$5:$C$104,$A9,'RFI Register'!$I$5:$I$104)) -> 0 | E9: =IF($A9="","",SUMIF('RFI Register'!$C$5:$C$104,$A9,'RFI Register'!$K$5:$K$104)) -> 0 | F9: =IF($A9="","",SUMIF('RFI Register'!$C$5:$C$104,$A9,'RFI Register'!$L$5:$L$104)) -> 0 | G9: =IF($A9="","",SUMIF('RFI Register'!$C$5:$C$104,$A9,'RFI Register'!$M$5:$M$104)) -> 0
A10: Civil Engineering | B10: =IF($A10="","",COUNTIF('RFI Register'!$C$5:$C$104,$A10)) -> 0 | C10: =IF($A10="","",COUNTIFS('RFI Register'!$C$5:$C$104,$A10,'RFI Register'!$H$5:$H$104,"<>Closed*",'RFI Register'!$H$5:$H$104,"<>Cancelled")) -> 0 | D10: =IF($A10="","",SUMIF('RFI Register'!$C$5:$C$104,$A10,'RFI Register'!$I$5:$I$104)) -> 0 | E10: =IF($A10="","",SUMIF('RFI Register'!$C$5:$C$104,$A10,'RFI Register'!$K$5:$K$104)) -> 0 | F10: =IF($A10="","",SUMIF('RFI Register'!$C$5:$C$104,$A10,'RFI Register'!$L$5:$L$104)) -> 0 | G10: =IF($A10="","",SUMIF('RFI Register'!$C$5:$C$104,$A10,'RFI Register'!$M$5:$M$104)) -> 0
A11: Structural Engineering | B11: =IF($A11="","",COUNTIF('RFI Register'!$C$5:$C$104,$A11)) -> 0 | C11: =IF($A11="","",COUNTIFS('RFI Register'!$C$5:$C$104,$A11,'RFI Register'!$H$5:$H$104,"<>Closed*",'RFI Register'!$H$5:$H$104,"<>Cancelled")) -> 0 | D11: =IF($A11="","",SUMIF('RFI Register'!$C$5:$C$104,$A11,'RFI Register'!$I$5:$I$104)) -> 0 | E11: =IF($A11="","",SUMIF('RFI Register'!$C$5:$C$104,$A11,'RFI Register'!$K$5:$K$104)) -> 0 | F11: =IF($A11="","",SUMIF('RFI Register'!$C$5:$C$104,$A11,'RFI Register'!$L$5:$L$104)) -> 0 | G11: =IF($A11="","",SUMIF('RFI Register'!$C$5:$C$104,$A11,'RFI Register'!$M$5:$M$104)) -> 0
A12: Electrical Engineering | B12: =IF($A12="","",COUNTIF('RFI Register'!$C$5:$C$104,$A12)) -> 0 | C12: =IF($A12="","",COUNTIFS('RFI Register'!$C$5:$C$104,$A12,'RFI Register'!$H$5:$H$104,"<>Closed*",'RFI Register'!$H$5:$H$104,"<>Cancelled")) -> 0 | D12: =IF($A12="","",SUMIF('RFI Register'!$C$5:$C$104,$A12,'RFI Register'!$I$5:$I$104)) -> 0 | E12: =IF($A12="","",SUMIF('RFI Register'!$C$5:$C$104,$A12,'RFI Register'!$K$5:$K$104)) -> 0 | F12: =IF($A12="","",SUMIF('RFI Register'!$C$5:$C$104,$A12,'RFI Register'!$L$5:$L$104)) -> 0 | G12: =IF($A12="","",SUMIF('RFI Register'!$C$5:$C$104,$A12,'RFI Register'!$M$5:$M$104)) -> 0
A13: Fire Protection Engineering | B13: =IF($A13="","",COUNTIF('RFI Register'!$C$5:$C$104,$A13)) -> 0 | C13: =IF($A13="","",COUNTIFS('RFI Register'!$C$5:$C$104,$A13,'RFI Register'!$H$5:$H$104,"<>Closed*",'RFI Register'!$H$5:$H$104,"<>Cancelled")) -> 0 | D13: =IF($A13="","",SUMIF('RFI Register'!$C$5:$C$104,$A13,'RFI Register'!$I$5:$I$104)) -> 0 | E13: =IF($A13="","",SUMIF('RFI Register'!$C$5:$C$104,$A13,'RFI Register'!$K$5:$K$104)) -> 0 | F13: =IF($A13="","",SUMIF('RFI Register'!$C$5:$C$104,$A13,'RFI Register'!$L$5:$L$104)) -> 0 | G13: =IF($A13="","",SUMIF('RFI Register'!$C$5:$C$104,$A13,'RFI Register'!$M$5:$M$104)) -> 0
A14: Owner's Engineer | B14: =IF($A14="","",COUNTIF('RFI Register'!$C$5:$C$104,$A14)) -> 0 | C14: =IF($A14="","",COUNTIFS('RFI Register'!$C$5:$C$104,$A14,'RFI Register'!$H$5:$H$104,"<>Closed*",'RFI Register'!$H$5:$H$104,"<>Cancelled")) -> 0 | D14: =IF($A14="","",SUMIF('RFI Register'!$C$5:$C$104,$A14,'RFI Register'!$I$5:$I$104)) -> 0 | E14: =IF($A14="","",SUMIF('RFI Register'!$C$5:$C$104,$A14,'RFI Register'!$K$5:$K$104)) -> 0 | F14: =IF($A14="","",SUMIF('RFI Register'!$C$5:$C$104,$A14,'RFI Register'!$L$5:$L$104)) -> 0 | G14: =IF($A14="","",SUMIF('RFI Register'!$C$5:$C$104,$A14,'RFI Register'!$M$5:$M$104)) -> 0
A15: Engineer of Record | B15: =IF($A15="","",COUNTIF('RFI Register'!$C$5:$C$104,$A15)) -> 0 | C15: =IF($A15="","",COUNTIFS('RFI Register'!$C$5:$C$104,$A15,'RFI Register'!$H$5:$H$104,"<>Closed*",'RFI Register'!$H$5:$H$104,"<>Cancelled")) -> 0 | D15: =IF($A15="","",SUMIF('RFI Register'!$C$5:$C$104,$A15,'RFI Register'!$I$5:$I$104)) -> 0 | E15: =IF($A15="","",SUMIF('RFI Register'!$C$5:$C$104,$A15,'RFI Register'!$K$5:$K$104)) -> 0 | F15: =IF($A15="","",SUMIF('RFI Register'!$C$5:$C$104,$A15,'RFI Register'!$L$5:$L$104)) -> 0 | G15: =IF($A15="","",SUMIF('RFI Register'!$C$5:$C$104,$A15,'RFI Register'!$M$5:$M$104)) -> 0
A16: Independent Engineer | B16: =IF($A16="","",COUNTIF('RFI Register'!$C$5:$C$104,$A16)) -> 0 | C16: =IF($A16="","",COUNTIFS('RFI Register'!$C$5:$C$104,$A16,'RFI Register'!$H$5:$H$104,"<>Closed*",'RFI Register'!$H$5:$H$104,"<>Cancelled")) -> 0 | D16: =IF($A16="","",SUMIF('RFI Register'!$C$5:$C$104,$A16,'RFI Register'!$I$5:$I$104)) -> 0 | E16: =IF($A16="","",SUMIF('RFI Register'!$C$5:$C$104,$A16,'RFI Register'!$K$5:$K$104)) -> 0 | F16: =IF($A16="","",SUMIF('RFI Register'!$C$5:$C$104,$A16,'RFI Register'!$L$5:$L$104)) -> 0 | G16: =IF($A16="","",SUMIF('RFI Register'!$C$5:$C$104,$A16,'RFI Register'!$M$5:$M$104)) -> 0
A17: BESS Equipment | B17: =IF($A17="","",COUNTIF('RFI Register'!$C$5:$C$104,$A17)) -> 1 | C17: =IF($A17="","",COUNTIFS('RFI Register'!$C$5:$C$104,$A17,'RFI Register'!$H$5:$H$104,"<>Closed*",'RFI Register'!$H$5:$H$104,"<>Cancelled")) -> 1 | D17: =IF($A17="","",SUMIF('RFI Register'!$C$5:$C$104,$A17,'RFI Register'!$I$5:$I$104)) -> 10 | E17: =IF($A17="","",SUMIF('RFI Register'!$C$5:$C$104,$A17,'RFI Register'!$K$5:$K$104)) -> 0 | F17: =IF($A17="","",SUMIF('RFI Register'!$C$5:$C$104,$A17,'RFI Register'!$L$5:$L$104)) -> 0 | G17: =IF($A17="","",SUMIF('RFI Register'!$C$5:$C$104,$A17,'RFI Register'!$M$5:$M$104)) -> 0
A18: MV Transformers | B18: =IF($A18="","",COUNTIF('RFI Register'!$C$5:$C$104,$A18)) -> 0 | C18: =IF($A18="","",COUNTIFS('RFI Register'!$C$5:$C$104,$A18,'RFI Register'!$H$5:$H$104,"<>Closed*",'RFI Register'!$H$5:$H$104,"<>Cancelled")) -> 0 | D18: =IF($A18="","",SUMIF('RFI Register'!$C$5:$C$104,$A18,'RFI Register'!$I$5:$I$104)) -> 0 | E18: =IF($A18="","",SUMIF('RFI Register'!$C$5:$C$104,$A18,'RFI Register'!$K$5:$K$104)) -> 0 | F18: =IF($A18="","",SUMIF('RFI Register'!$C$5:$C$104,$A18,'RFI Register'!$L$5:$L$104)) -> 0 | G18: =IF($A18="","",SUMIF('RFI Register'!$C$5:$C$104,$A18,'RFI Register'!$M$5:$M$104)) -> 0
A19: HV Breakers | B19: =IF($A19="","",COUNTIF('RFI Register'!$C$5:$C$104,$A19)) -> 0 | C19: =IF($A19="","",COUNTIFS('RFI Register'!$C$5:$C$104,$A19,'RFI Register'!$H$5:$H$104,"<>Closed*",'RFI Register'!$H$5:$H$104,"<>Cancelled")) -> 0 | D19: =IF($A19="","",SUMIF('RFI Register'!$C$5:$C$104,$A19,'RFI Register'!$I$5:$I$104)) -> 0 | E19: =IF($A19="","",SUMIF('RFI Register'!$C$5:$C$104,$A19,'RFI Register'!$K$5:$K$104)) -> 0 | F19: =IF($A19="","",SUMIF('RFI Register'!$C$5:$C$104,$A19,'RFI Register'!$L$5:$L$104)) -> 0 | G19: =IF($A19="","",SUMIF('RFI Register'!$C$5:$C$104,$A19,'RFI Register'!$M$5:$M$104)) -> 0
A20: MV Breakers / Switchgear | B20: =IF($A20="","",COUNTIF('RFI Register'!$C$5:$C$104,$A20)) -> 0 | C20: =IF($A20="","",COUNTIFS('RFI Register'!$C$5:$C$104,$A20,'RFI Register'!$H$5:$H$104,"<>Closed*",'RFI Register'!$H$5:$H$104,"<>Cancelled")) -> 0 | D20: =IF($A20="","",SUMIF('RFI Register'!$C$5:$C$104,$A20,'RFI Register'!$I$5:$I$104)) -> 0 | E20: =IF($A20="","",SUMIF('RFI Register'!$C$5:$C$104,$A20,'RFI Register'!$K$5:$K$104)) -> 0 | F20: =IF($A20="","",SUMIF('RFI Register'!$C$5:$C$104,$A20,'RFI Register'!$L$5:$L$104)) -> 0 | G20: =IF($A20="","",SUMIF('RFI Register'!$C$5:$C$104,$A20,'RFI Register'!$M$5:$M$104)) -> 0
... A22: Software | B22: =IF($A22="","",COUNTIF('RFI Register'!$C$5:$C$104,$A22)) -> 0 | C22: =IF($A22="","",COUNTIFS('RFI Register'!$C$5:$C$104,$A22,'RFI Register'!$H$5:$H$104,"<>Closed*",'RFI Register'!$H$5:$H$104,"<>Cancelled")) -> 0 | D22: =IF($A22="","",SUMIF('RFI Register'!$C$5:$C$104,$A22,'RFI Register'!$I$5:$I$104)) -> 0 | E22: =IF($A22="","",SUMIF('RFI Register'!$C$5:$C$104,$A22,'RFI Register'!$K$5:$K$104)) -> 0 | F22: =IF($A22="","",SUMIF('RFI Register'!$C$5:$C$104,$A22,'RFI Register'!$L$5:$L$104)) -> 0 | G22: =IF($A22="","",SUMIF('RFI Register'!$C$5:$C$104,$A22,'RFI Register'!$M$5:$M$104)) -> 0
A24: By project
A25: Project | B25: RFIs | C25: Active | D25: Vendors Invited | E25: Responses | F25: Actions Overdue | G25: Key Item Fails
A26: =IF(Projects!$B$5="","",Projects!$B$5) -> Seven Angels BESS | B26: =IF($A26="","",COUNTIF('RFI Register'!$B$5:$B$104,$A26)) -> 0 | C26: =IF($A26="","",COUNTIFS('RFI Register'!$B$5:$B$104,$A26,'RFI Register'!$H$5:$H$104,"<>Closed*",'RFI Register'!$H$5:$H$104,"<>Cancelled")) -> 0 | D26: =IF($A26="","",SUMIF('RFI Register'!$B$5:$B$104,$A26,'RFI Register'!$I$5:$I$104)) -> 0 | E26: =IF($A26="","",SUMIF('RFI Register'!$B$5:$B$104,$A26,'RFI Register'!$K$5:$K$104)) -> 0 | F26: =IF($A26="","",SUMIF('RFI Register'!$B$5:$B$104,$A26,'RFI Register'!$L$5:$L$104)) -> 0 | G26: =IF($A26="","",SUMIF('RFI Register'!$B$5:$B$104,$A26,'RFI Register'!$M$5:$M$104)) -> 0
A27: =IF(Projects!$B$6="","",Projects!$B$6) -> Project B (placeholder - rename) | B27: =IF($A27="","",COUNTIF('RFI Register'!$B$5:$B$104,$A27)) -> 0 | C27: =IF($A27="","",COUNTIFS('RFI Register'!$B$5:$B$104,$A27,'RFI Register'!$H$5:$H$104,"<>Closed*",'RFI Register'!$H$5:$H$104,"<>Cancelled")) -> 0 | D27: =IF($A27="","",SUMIF('RFI Register'!$B$5:$B$104,$A27,'RFI Register'!$I$5:$I$104)) -> 0 | E27: =IF($A27="","",SUMIF('RFI Register'!$B$5:$B$104,$A27,'RFI Register'!$K$5:$K$104)) -> 0 | F27: =IF($A27="","",SUMIF('RFI Register'!$B$5:$B$104,$A27,'RFI Register'!$L$5:$L$104)) -> 0 | G27: =IF($A27="","",SUMIF('RFI Register'!$B$5:$B$104,$A27,'RFI Register'!$M$5:$M$104)) -> 0
A28: =IF(Projects!$B$7="","",Projects!$B$7) -> Project C (placeholder - rename) | B28: =IF($A28="","",COUNTIF('RFI Register'!$B$5:$B$104,$A28)) -> 0 | C28: =IF($A28="","",COUNTIFS('RFI Register'!$B$5:$B$104,$A28,'RFI Register'!$H$5:$H$104,"<>Closed*",'RFI Register'!$H$5:$H$104,"<>Cancelled")) -> 0 | D28: =IF($A28="","",SUMIF('RFI Register'!$B$5:$B$104,$A28,'RFI Register'!$I$5:$I$104)) -> 0 | E28: =IF($A28="","",SUMIF('RFI Register'!$B$5:$B$104,$A28,'RFI Register'!$K$5:$K$104)) -> 0 | F28: =IF($A28="","",SUMIF('RFI Register'!$B$5:$B$104,$A28,'RFI Register'!$L$5:$L$104)) -> 0 | G28: =IF($A28="","",SUMIF('RFI Register'!$B$5:$B$104,$A28,'RFI Register'!$M$5:$M$104)) -> 0
A29: =IF(Projects!$B$8="","",Projects!$B$8) | B29: =IF($A29="","",COUNTIF('RFI Register'!$B$5:$B$104,$A29)) | C29: =IF($A29="","",COUNTIFS('RFI Register'!$B$5:$B$104,$A29,'RFI Register'!$H$5:$H$104,"<>Closed*",'RFI Register'!$H$5:$H$104,"<>Cancelled")) | D29: =IF($A29="","",SUMIF('RFI Register'!$B$5:$B$104,$A29,'RFI Register'!$I$5:$I$104)) | E29: =IF($A29="","",SUMIF('RFI Register'!$B$5:$B$104,$A29,'RFI Register'!$K$5:$K$104)) | F29: =IF($A29="","",SUMIF('RFI Register'!$B$5:$B$104,$A29,'RFI Register'!$L$5:$L$104)) | G29: =IF($A29="","",SUMIF('RFI Register'!$B$5:$B$104,$A29,'RFI Register'!$M$5:$M$104))
A30: =IF(Projects!$B$9="","",Projects!$B$9) | B30: =IF($A30="","",COUNTIF('RFI Register'!$B$5:$B$104,$A30)) | C30: =IF($A30="","",COUNTIFS('RFI Register'!$B$5:$B$104,$A30,'RFI Register'!$H$5:$H$104,"<>Closed*",'RFI Register'!$H$5:$H$104,"<>Cancelled")) | D30: =IF($A30="","",SUMIF('RFI Register'!$B$5:$B$104,$A30,'RFI Register'!$I$5:$I$104)) | E30: =IF($A30="","",SUMIF('RFI Register'!$B$5:$B$104,$A30,'RFI Register'!$K$5:$K$104)) | F30: =IF($A30="","",SUMIF('RFI Register'!$B$5:$B$104,$A30,'RFI Register'!$L$5:$L$104)) | G30: =IF($A30="","",SUMIF('RFI Register'!$B$5:$B$104,$A30,'RFI Register'!$M$5:$M$104))
A31: =IF(Projects!$B$10="","",Projects!$B$10) | B31: =IF($A31="","",COUNTIF('RFI Register'!$B$5:$B$104,$A31)) | C31: =IF($A31="","",COUNTIFS('RFI Register'!$B$5:$B$104,$A31,'RFI Register'!$H$5:$H$104,"<>Closed*",'RFI Register'!$H$5:$H$104,"<>Cancelled")) | D31: =IF($A31="","",SUMIF('RFI Register'!$B$5:$B$104,$A31,'RFI Register'!$I$5:$I$104)) | E31: =IF($A31="","",SUMIF('RFI Register'!$B$5:$B$104,$A31,'RFI Register'!$K$5:$K$104)) | F31: =IF($A31="","",SUMIF('RFI Register'!$B$5:$B$104,$A31,'RFI Register'!$L$5:$L$104)) | G31: =IF($A31="","",SUMIF('RFI Register'!$B$5:$B$104,$A31,'RFI Register'!$M$5:$M$104))
A32: =IF(Projects!$B$11="","",Projects!$B$11) | B32: =IF($A32="","",COUNTIF('RFI Register'!$B$5:$B$104,$A32)) | C32: =IF($A32="","",COUNTIFS('RFI Register'!$B$5:$B$104,$A32,'RFI Register'!$H$5:$H$104,"<>Closed*",'RFI Register'!$H$5:$H$104,"<>Cancelled")) | D32: =IF($A32="","",SUMIF('RFI Register'!$B$5:$B$104,$A32,'RFI Register'!$I$5:$I$104)) | E32: =IF($A32="","",SUMIF('RFI Register'!$B$5:$B$104,$A32,'RFI Register'!$K$5:$K$104)) | F32: =IF($A32="","",SUMIF('RFI Register'!$B$5:$B$104,$A32,'RFI Register'!$L$5:$L$104)) | G32: =IF($A32="","",SUMIF('RFI Register'!$B$5:$B$104,$A32,'RFI Register'!$M$5:$M$104))
A33: =IF(Projects!$B$12="","",Projects!$B$12) | B33: =IF($A33="","",COUNTIF('RFI Register'!$B$5:$B$104,$A33)) | C33: =IF($A33="","",COUNTIFS('RFI Register'!$B$5:$B$104,$A33,'RFI Register'!$H$5:$H$104,"<>Closed*",'RFI Register'!$H$5:$H$104,"<>Cancelled")) | D33: =IF($A33="","",SUMIF('RFI Register'!$B$5:$B$104,$A33,'RFI Register'!$I$5:$I$104)) | E33: =IF($A33="","",SUMIF('RFI Register'!$B$5:$B$104,$A33,'RFI Register'!$K$5:$K$104)) | F33: =IF($A33="","",SUMIF('RFI Register'!$B$5:$B$104,$A33,'RFI Register'!$L$5:$L$104)) | G33: =IF($A33="","",SUMIF('RFI Register'!$B$5:$B$104,$A33,'RFI Register'!$M$5:$M$104))
A34: =IF(Projects!$B$13="","",Projects!$B$13) | B34: =IF($A34="","",COUNTIF('RFI Register'!$B$5:$B$104,$A34)) | C34: =IF($A34="","",COUNTIFS('RFI Register'!$B$5:$B$104,$A34,'RFI Register'!$H$5:$H$104,"<>Closed*",'RFI Register'!$H$5:$H$104,"<>Cancelled")) | D34: =IF($A34="","",SUMIF('RFI Register'!$B$5:$B$104,$A34,'RFI Register'!$I$5:$I$104)) | E34: =IF($A34="","",SUMIF('RFI Register'!$B$5:$B$104,$A34,'RFI Register'!$K$5:$K$104)) | F34: =IF($A34="","",SUMIF('RFI Register'!$B$5:$B$104,$A34,'RFI Register'!$L$5:$L$104)) | G34: =IF($A34="","",SUMIF('RFI Register'!$B$5:$B$104,$A34,'RFI Register'!$M$5:$M$104))
A35: =IF(Projects!$B$14="","",Projects!$B$14) | B35: =IF($A35="","",COUNTIF('RFI Register'!$B$5:$B$104,$A35)) | C35: =IF($A35="","",COUNTIFS('RFI Register'!$B$5:$B$104,$A35,'RFI Register'!$H$5:$H$104,"<>Closed*",'RFI Register'!$H$5:$H$104,"<>Cancelled")) | D35: =IF($A35="","",SUMIF('RFI Register'!$B$5:$B$104,$A35,'RFI Register'!$I$5:$I$104)) | E35: =IF($A35="","",SUMIF('RFI Register'!$B$5:$B$104,$A35,'RFI Register'!$K$5:$K$104)) | F35: =IF($A35="","",SUMIF('RFI Register'!$B$5:$B$104,$A35,'RFI Register'!$L$5:$L$104)) | G35: =IF($A35="","",SUMIF('RFI Register'!$B$5:$B$104,$A35,'RFI Register'!$M$5:$M$104))
A36: =IF(Projects!$B$15="","",Projects!$B$15) | B36: =IF($A36="","",COUNTIF('RFI Register'!$B$5:$B$104,$A36)) | C36: =IF($A36="","",COUNTIFS('RFI Register'!$B$5:$B$104,$A36,'RFI Register'!$H$5:$H$104,"<>Closed*",'RFI Register'!$H$5:$H$104,"<>Cancelled")) | D36: =IF($A36="","",SUMIF('RFI Register'!$B$5:$B$104,$A36,'RFI Register'!$I$5:$I$104)) | E36: =IF($A36="","",SUMIF('RFI Register'!$B$5:$B$104,$A36,'RFI Register'!$K$5:$K$104)) | F36: =IF($A36="","",SUMIF('RFI Register'!$B$5:$B$104,$A36,'RFI Register'!$L$5:$L$104)) | G36: =IF($A36="","",SUMIF('RFI Register'!$B$5:$B$104,$A36,'RFI Register'!$M$5:$M$104))
A37: =IF(Projects!$B$16="","",Projects!$B$16) | B37: =IF($A37="","",COUNTIF('RFI Register'!$B$5:$B$104,$A37)) | C37: =IF($A37="","",COUNTIFS('RFI Register'!$B$5:$B$104,$A37,'RFI Register'!$H$5:$H$104,"<>Closed*",'RFI Register'!$H$5:$H$104,"<>Cancelled")) | D37: =IF($A37="","",SUMIF('RFI Register'!$B$5:$B$104,$A37,'RFI Register'!$I$5:$I$104)) | E37: =IF($A37="","",SUMIF('RFI Register'!$B$5:$B$104,$A37,'RFI Register'!$K$5:$K$104)) | F37: =IF($A37="","",SUMIF('RFI Register'!$B$5:$B$104,$A37,'RFI Register'!$L$5:$L$104)) | G37: =IF($A37="","",SUMIF('RFI Register'!$B$5:$B$104,$A37,'RFI Register'!$M$5:$M$104))
A38: =IF(Projects!$B$17="","",Projects!$B$17) | B38: =IF($A38="","",COUNTIF('RFI Register'!$B$5:$B$104,$A38)) | C38: =IF($A38="","",COUNTIFS('RFI Register'!$B$5:$B$104,$A38,'RFI Register'!$H$5:$H$104,"<>Closed*",'RFI Register'!$H$5:$H$104,"<>Cancelled")) | D38: =IF($A38="","",SUMIF('RFI Register'!$B$5:$B$104,$A38,'RFI Register'!$I$5:$I$104)) | E38: =IF($A38="","",SUMIF('RFI Register'!$B$5:$B$104,$A38,'RFI Register'!$K$5:$K$104)) | F38: =IF($A38="","",SUMIF('RFI Register'!$B$5:$B$104,$A38,'RFI Register'!$L$5:$L$104)) | G38: =IF($A38="","",SUMIF('RFI Register'!$B$5:$B$104,$A38,'RFI Register'!$M$5:$M$104))
A39: =IF(Projects!$B$18="","",Projects!$B$18) | B39: =IF($A39="","",COUNTIF('RFI Register'!$B$5:$B$104,$A39)) | C39: =IF($A39="","",COUNTIFS('RFI Register'!$B$5:$B$104,$A39,'RFI Register'!$H$5:$H$104,"<>Closed*",'RFI Register'!$H$5:$H$104,"<>Cancelled")) | D39: =IF($A39="","",SUMIF('RFI Register'!$B$5:$B$104,$A39,'RFI Register'!$I$5:$I$104)) | E39: =IF($A39="","",SUMIF('RFI Register'!$B$5:$B$104,$A39,'RFI Register'!$K$5:$K$104)) | F39: =IF($A39="","",SUMIF('RFI Register'!$B$5:$B$104,$A39,'RFI Register'!$L$5:$L$104)) | G39: =IF($A39="","",SUMIF('RFI Register'!$B$5:$B$104,$A39,'RFI Register'!$M$5:$M$104))
A40: =IF(Projects!$B$19="","",Projects!$B$19) | B40: =IF($A40="","",COUNTIF('RFI Register'!$B$5:$B$104,$A40)) | C40: =IF($A40="","",COUNTIFS('RFI Register'!$B$5:$B$104,$A40,'RFI Register'!$H$5:$H$104,"<>Closed*",'RFI Register'!$H$5:$H$104,"<>Cancelled")) | D40: =IF($A40="","",SUMIF('RFI Register'!$B$5:$B$104,$A40,'RFI Register'!$I$5:$I$104)) | E40: =IF($A40="","",SUMIF('RFI Register'!$B$5:$B$104,$A40,'RFI Register'!$K$5:$K$104)) | F40: =IF($A40="","",SUMIF('RFI Register'!$B$5:$B$104,$A40,'RFI Register'!$L$5:$L$104)) | G40: =IF($A40="","",SUMIF('RFI Register'!$B$5:$B$104,$A40,'RFI Register'!$M$5:$M$104))

Sheet RFI Register
A1: RFI Register
A2: One row per RFI activity. Type the RFI ID (= tab name) in column A; the grey columns fill in from that tab. Add the outcome and notes in yellow.
A4: RFI ID (tab name) | B4: Project | C4: Vendor Type | D4: RFI Title / Scope | E4: RFI Owner | F4: Issue Date | G4: Response Due | H4: Activity Status | I4: Vendors Invited | J4: RFIs Sent | K4: Responses | L4: Actions Overdue | M4: Key Items Fails | N4: Days to Due | O4: Outcome / Next RFx Step | P4: Notes
A5: RFI-001 | B5: =IF($A5="","",IFERROR(INDIRECT("'"&$A5&"'!C4")&"","Tab not found")) -> Project A (placeholder - rename) | C5: =IF($A5="","",IFERROR(INDIRECT("'"&$A5&"'!C5")&"","Tab not found")) -> BESS Equipment | D5: =IF($A5="","",IFERROR(INDIRECT("'"&$A5&"'!C6")&"","Tab not found")) -> EXAMPLE - BESS equipment RFI (repurpose or delete) | E5: =IF($A5="","",IFERROR(INDIRECT("'"&$A5&"'!C7")&"","Tab not found")) -> Jason Knedlhans | F5: =IF($A5="","",IFERROR(IF(INDIRECT("'"&$A5&"'!C8")="","",INDIRECT("'"&$A5&"'!C8")),"Tab not found")) | G5: =IF($A5="","",IFERROR(IF(INDIRECT("'"&$A5&"'!C9")="","",INDIRECT("'"&$A5&"'!C9")),"Tab not found")) | H5: =IF($A5="","",IFERROR(INDIRECT("'"&$A5&"'!C10")&"","Tab not found")) -> Planning | I5: =IF($A5="","",IFERROR(IF(INDIRECT("'"&$A5&"'!I3")="","",INDIRECT("'"&$A5&"'!I3")+0),"Tab not found")) -> 10 | J5: =IF($A5="","",IFERROR(IF(INDIRECT("'"&$A5&"'!I4")="","",INDIRECT("'"&$A5&"'!I4")+0),"Tab not found")) -> 0 | K5: =IF($A5="","",IFERROR(IF(INDIRECT("'"&$A5&"'!I5")="","",INDIRECT("'"&$A5&"'!I5")+0),"Tab not found")) -> 0 | L5: =IF($A5="","",IFERROR(IF(INDIRECT("'"&$A5&"'!I7")="","",INDIRECT("'"&$A5&"'!I7")+0),"Tab not found")) -> 0 | M5: =IF($A5="","",IFERROR(IF(INDIRECT("'"&$A5&"'!I9")="","",INDIRECT("'"&$A5&"'!I9")+0),"Tab not found")) -> 0 | N5: =IF($A5="","",IFERROR(IF(INDIRECT("'"&$A5&"'!I10")="","",INDIRECT("'"&$A5&"'!I10")+0),"Tab not found")) | P5: Example tab - repurpose for the first real RFI or delete this row and the tab.
B6: =IF($A6="","",IFERROR(INDIRECT("'"&$A6&"'!C4")&"","Tab not found")) | C6: =IF($A6="","",IFERROR(INDIRECT("'"&$A6&"'!C5")&"","Tab not found")) | D6: =IF($A6="","",IFERROR(INDIRECT("'"&$A6&"'!C6")&"","Tab not found")) | E6: =IF($A6="","",IFERROR(INDIRECT("'"&$A6&"'!C7")&"","Tab not found")) | F6: =IF($A6="","",IFERROR(IF(INDIRECT("'"&$A6&"'!C8")="","",INDIRECT("'"&$A6&"'!C8")),"Tab not found")) | G6: =IF($A6="","",IFERROR(IF(INDIRECT("'"&$A6&"'!C9")="","",INDIRECT("'"&$A6&"'!C9")),"Tab not found")) | H6: =IF($A6="","",IFERROR(INDIRECT("'"&$A6&"'!C10")&"","Tab not found")) | I6: =IF($A6="","",IFERROR(IF(INDIRECT("'"&$A6&"'!I3")="","",INDIRECT("'"&$A6&"'!I3")+0),"Tab not found")) | J6: =IF($A6="","",IFERROR(IF(INDIRECT("'"&$A6&"'!I4")="","",INDIRECT("'"&$A6&"'!I4")+0),"Tab not found")) | K6: =IF($A6="","",IFERROR(IF(INDIRECT("'"&$A6&"'!I5")="","",INDIRECT("'"&$A6&"'!I5")+0),"Tab not found")) | L6: =IF($A6="","",IFERROR(IF(INDIRECT("'"&$A6&"'!I7")="","",INDIRECT("'"&$A6&"'!I7")+0),"Tab not found")) | M6: =IF($A6="","",IFERROR(IF(INDIRECT("'"&$A6&"'!I9")="","",INDIRECT("'"&$A6&"'!I9")+0),"Tab not found")) | N6: =IF($A6="","",IFERROR(IF(INDIRECT("'"&$A6&"'!I10")="","",INDIRECT("'"&$A6&"'!I10")+0),"Tab not found"))
B7: =IF($A7="","",IFERROR(INDIRECT("'"&$A7&"'!C4")&"","Tab not found")) | C7: =IF($A7="","",IFERROR(INDIRECT("'"&$A7&"'!C5")&"","Tab not found")) | D7: =IF($A7="","",IFERROR(INDIRECT("'"&$A7&"'!C6")&"","Tab not found")) | E7: =IF($A7="","",IFERROR(INDIRECT("'"&$A7&"'!C7")&"","Tab not found")) | F7: =IF($A7="","",IFERROR(IF(INDIRECT("'"&$A7&"'!C8")="","",INDIRECT("'"&$A7&"'!C8")),"Tab not found")) | G7: =IF($A7="","",IFERROR(IF(INDIRECT("'"&$A7&"'!C9")="","",INDIRECT("'"&$A7&"'!C9")),"Tab not found")) | H7: =IF($A7="","",IFERROR(INDIRECT("'"&$A7&"'!C10")&"","Tab not found")) | I7: =IF($A7="","",IFERROR(IF(INDIRECT("'"&$A7&"'!I3")="","",INDIRECT("'"&$A7&"'!I3")+0),"Tab not found")) | J7: =IF($A7="","",IFERROR(IF(INDIRECT("'"&$A7&"'!I4")="","",INDIRECT("'"&$A7&"'!I4")+0),"Tab not found")) | K7: =IF($A7="","",IFERROR(IF(INDIRECT("'"&$A7&"'!I5")="","",INDIRECT("'"&$A7&"'!I5")+0),"Tab not found")) | L7: =IF($A7="","",IFERROR(IF(INDIRECT("'"&$A7&"'!I7")="","",INDIRECT("'"&$A7&"'!I7")+0),"Tab not found")) | M7: =IF($A7="","",IFERROR(IF(INDIRECT("'"&$A7&"'!I9")="","",INDIRECT("'"&$A7&"'!I9")+0),"Tab not found")) | N7: =IF($A7="","",IFERROR(IF(INDIRECT("'"&$A7&"'!I10")="","",INDIRECT("'"&$A7&"'!I10")+0),"Tab not found"))
B8: =IF($A8="","",IFERROR(INDIRECT("'"&$A8&"'!C4")&"","Tab not found")) | C8: =IF($A8="","",IFERROR(INDIRECT("'"&$A8&"'!C5")&"","Tab not found")) | D8: =IF($A8="","",IFERROR(INDIRECT("'"&$A8&"'!C6")&"","Tab not found")) | E8: =IF($A8="","",IFERROR(INDIRECT("'"&$A8&"'!C7")&"","Tab not found")) | F8: =IF($A8="","",IFERROR(IF(INDIRECT("'"&$A8&"'!C8")="","",INDIRECT("'"&$A8&"'!C8")),"Tab not found")) | G8: =IF($A8="","",IFERROR(IF(INDIRECT("'"&$A8&"'!C9")="","",INDIRECT("'"&$A8&"'!C9")),"Tab not found")) | H8: =IF($A8="","",IFERROR(INDIRECT("'"&$A8&"'!C10")&"","Tab not found")) | I8: =IF($A8="","",IFERROR(IF(INDIRECT("'"&$A8&"'!I3")="","",INDIRECT("'"&$A8&"'!I3")+0),"Tab not found")) | J8: =IF($A8="","",IFERROR(IF(INDIRECT("'"&$A8&"'!I4")="","",INDIRECT("'"&$A8&"'!I4")+0),"Tab not found")) | K8: =IF($A8="","",IFERROR(IF(INDIRECT("'"&$A8&"'!I5")="","",INDIRECT("'"&$A8&"'!I5")+0),"Tab not found")) | L8: =IF($A8="","",IFERROR(IF(INDIRECT("'"&$A8&"'!I7")="","",INDIRECT("'"&$A8&"'!I7")+0),"Tab not found")) | M8: =IF($A8="","",IFERROR(IF(INDIRECT("'"&$A8&"'!I9")="","",INDIRECT("'"&$A8&"'!I9")+0),"Tab not found")) | N8: =IF($A8="","",IFERROR(IF(INDIRECT("'"&$A8&"'!I10")="","",INDIRECT("'"&$A8&"'!I10")+0),"Tab not found"))
B9: =IF($A9="","",IFERROR(INDIRECT("'"&$A9&"'!C4")&"","Tab not found")) | C9: =IF($A9="","",IFERROR(INDIRECT("'"&$A9&"'!C5")&"","Tab not found")) | D9: =IF($A9="","",IFERROR(INDIRECT("'"&$A9&"'!C6")&"","Tab not found")) | E9: =IF($A9="","",IFERROR(INDIRECT("'"&$A9&"'!C7")&"","Tab not found")) | F9: =IF($A9="","",IFERROR(IF(INDIRECT("'"&$A9&"'!C8")="","",INDIRECT("'"&$A9&"'!C8")),"Tab not found")) | G9: =IF($A9="","",IFERROR(IF(INDIRECT("'"&$A9&"'!C9")="","",INDIRECT("'"&$A9&"'!C9")),"Tab not found")) | H9: =IF($A9="","",IFERROR(INDIRECT("'"&$A9&"'!C10")&"","Tab not found")) | I9: =IF($A9="","",IFERROR(IF(INDIRECT("'"&$A9&"'!I3")="","",INDIRECT("'"&$A9&"'!I3")+0),"Tab not found")) | J9: =IF($A9="","",IFERROR(IF(INDIRECT("'"&$A9&"'!I4")="","",INDIRECT("'"&$A9&"'!I4")+0),"Tab not found")) | K9: =IF($A9="","",IFERROR(IF(INDIRECT("'"&$A9&"'!I5")="","",INDIRECT("'"&$A9&"'!I5")+0),"Tab not found")) | L9: =IF($A9="","",IFERROR(IF(INDIRECT("'"&$A9&"'!I7")="","",INDIRECT("'"&$A9&"'!I7")+0),"Tab not found")) | M9: =IF($A9="","",IFERROR(IF(INDIRECT("'"&$A9&"'!I9")="","",INDIRECT("'"&$A9&"'!I9")+0),"Tab not found")) | N9: =IF($A9="","",IFERROR(IF(INDIRECT("'"&$A9&"'!I10")="","",INDIRECT("'"&$A9&"'!I10")+0),"Tab not found"))
B10: =IF($A10="","",IFERROR(INDIRECT("'"&$A10&"'!C4")&"","Tab not found")) | C10: =IF($A10="","",IFERROR(INDIRECT("'"&$A10&"'!C5")&"","Tab not found")) | D10: =IF($A10="","",IFERROR(INDIRECT("'"&$A10&"'!C6")&"","Tab not found")) | E10: =IF($A10="","",IFERROR(INDIRECT("'"&$A10&"'!C7")&"","Tab not found")) | F10: =IF($A10="","",IFERROR(IF(INDIRECT("'"&$A10&"'!C8")="","",INDIRECT("'"&$A10&"'!C8")),"Tab not found")) | G10: =IF($A10="","",IFERROR(IF(INDIRECT("'"&$A10&"'!C9")="","",INDIRECT("'"&$A10&"'!C9")),"Tab not found")) | H10: =IF($A10="","",IFERROR(INDIRECT("'"&$A10&"'!C10")&"","Tab not found")) | I10: =IF($A10="","",IFERROR(IF(INDIRECT("'"&$A10&"'!I3")="","",INDIRECT("'"&$A10&"'!I3")+0),"Tab not found")) | J10: =IF($A10="","",IFERROR(IF(INDIRECT("'"&$A10&"'!I4")="","",INDIRECT("'"&$A10&"'!I4")+0),"Tab not found")) | K10: =IF($A10="","",IFERROR(IF(INDIRECT("'"&$A10&"'!I5")="","",INDIRECT("'"&$A10&"'!I5")+0),"Tab not found")) | L10: =IF($A10="","",IFERROR(IF(INDIRECT("'"&$A10&"'!I7")="","",INDIRECT("'"&$A10&"'!I7")+0),"Tab not found")) | M10: =IF($A10="","",IFERROR(IF(INDIRECT("'"&$A10&"'!I9")="","",INDIRECT("'"&$A10&"'!I9")+0),"Tab not found")) | N10: =IF($A10="","",IFERROR(IF(INDIRECT("'"&$A10&"'!I10")="","",INDIRECT("'"&$A10&"'!I10")+0),"Tab not found"))
B11: =IF($A11="","",IFERROR(INDIRECT("'"&$A11&"'!C4")&"","Tab not found")) | C11: =IF($A11="","",IFERROR(INDIRECT("'"&$A11&"'!C5")&"","Tab not found")) | D11: =IF($A11="","",IFERROR(INDIRECT("'"&$A11&"'!C6")&"","Tab not found")) | E11: =IF($A11="","",IFERROR(INDIRECT("'"&$A11&"'!C7")&"","Tab not found")) | F11: =IF($A11="","",IFERROR(IF(INDIRECT("'"&$A11&"'!C8")="","",INDIRECT("'"&$A11&"'!C8")),"Tab not found")) | G11: =IF($A11="","",IFERROR(IF(INDIRECT("'"&$A11&"'!C9")="","",INDIRECT("'"&$A11&"'!C9")),"Tab not found")) | H11: =IF($A11="","",IFERROR(INDIRECT("'"&$A11&"'!C10")&"","Tab not found")) | I11: =IF($A11="","",IFERROR(IF(INDIRECT("'"&$A11&"'!I3")="","",INDIRECT("'"&$A11&"'!I3")+0),"Tab not found")) | J11: =IF($A11="","",IFERROR(IF(INDIRECT("'"&$A11&"'!I4")="","",INDIRECT("'"&$A11&"'!I4")+0),"Tab not found")) | K11: =IF($A11="","",IFERROR(IF(INDIRECT("'"&$A11&"'!I5")="","",INDIRECT("'"&$A11&"'!I5")+0),"Tab not found")) | L11: =IF($A11="","",IFERROR(IF(INDIRECT("'"&$A11&"'!I7")="","",INDIRECT("'"&$A11&"'!I7")+0),"Tab not found")) | M11: =IF($A11="","",IFERROR(IF(INDIRECT("'"&$A11&"'!I9")="","",INDIRECT("'"&$A11&"'!I9")+0),"Tab not found")) | N11: =IF($A11="","",IFERROR(IF(INDIRECT("'"&$A11&"'!I10")="","",INDIRECT("'"&$A11&"'!I10")+0),"Tab not found"))
B12: =IF($A12="","",IFERROR(INDIRECT("'"&$A12&"'!C4")&"","Tab not found")) | C12: =IF($A12="","",IFERROR(INDIRECT("'"&$A12&"'!C5")&"","Tab not found")) | D12: =IF($A12="","",IFERROR(INDIRECT("'"&$A12&"'!C6")&"","Tab not found")) | E12: =IF($A12="","",IFERROR(INDIRECT("'"&$A12&"'!C7")&"","Tab not found")) | F12: =IF($A12="","",IFERROR(IF(INDIRECT("'"&$A12&"'!C8")="","",INDIRECT("'"&$A12&"'!C8")),"Tab not found")) | G12: =IF($A12="","",IFERROR(IF(INDIRECT("'"&$A12&"'!C9")="","",INDIRECT("'"&$A12&"'!C9")),"Tab not found")) | H12: =IF($A12="","",IFERROR(INDIRECT("'"&$A12&"'!C10")&"","Tab not found")) | I12: =IF($A12="","",IFERROR(IF(INDIRECT("'"&$A12&"'!I3")="","",INDIRECT("'"&$A12&"'!I3")+0),"Tab not found")) | J12: =IF($A12="","",IFERROR(IF(INDIRECT("'"&$A12&"'!I4")="","",INDIRECT("'"&$A12&"'!I4")+0),"Tab not found")) | K12: =IF($A12="","",IFERROR(IF(INDIRECT("'"&$A12&"'!I5")="","",INDIRECT("'"&$A12&"'!I5")+0),"Tab not found")) | L12: =IF($A12="","",IFERROR(IF(INDIRECT("'"&$A12&"'!I7")="","",INDIRECT("'"&$A12&"'!I7")+0),"Tab not found")) | M12: =IF($A12="","",IFERROR(IF(INDIRECT("'"&$A12&"'!I9")="","",INDIRECT("'"&$A12&"'!I9")+0),"Tab not found")) | N12: =IF($A12="","",IFERROR(IF(INDIRECT("'"&$A12&"'!I10")="","",INDIRECT("'"&$A12&"'!I10")+0),"Tab not found"))
B13: =IF($A13="","",IFERROR(INDIRECT("'"&$A13&"'!C4")&"","Tab not found")) | C13: =IF($A13="","",IFERROR(INDIRECT("'"&$A13&"'!C5")&"","Tab not found")) | D13: =IF($A13="","",IFERROR(INDIRECT("'"&$A13&"'!C6")&"","Tab not found")) | E13: =IF($A13="","",IFERROR(INDIRECT("'"&$A13&"'!C7")&"","Tab not found")) | F13: =IF($A13="","",IFERROR(IF(INDIRECT("'"&$A13&"'!C8")="","",INDIRECT("'"&$A13&"'!C8")),"Tab not found")) | G13: =IF($A13="","",IFERROR(IF(INDIRECT("'"&$A13&"'!C9")="","",INDIRECT("'"&$A13&"'!C9")),"Tab not found")) | H13: =IF($A13="","",IFERROR(INDIRECT("'"&$A13&"'!C10")&"","Tab not found")) | I13: =IF($A13="","",IFERROR(IF(INDIRECT("'"&$A13&"'!I3")="","",INDIRECT("'"&$A13&"'!I3")+0),"Tab not found")) | J13: =IF($A13="","",IFERROR(IF(INDIRECT("'"&$A13&"'!I4")="","",INDIRECT("'"&$A13&"'!I4")+0),"Tab not found")) | K13: =IF($A13="","",IFERROR(IF(INDIRECT("'"&$A13&"'!I5")="","",INDIRECT("'"&$A13&"'!I5")+0),"Tab not found")) | L13: =IF($A13="","",IFERROR(IF(INDIRECT("'"&$A13&"'!I7")="","",INDIRECT("'"&$A13&"'!I7")+0),"Tab not found")) | M13: =IF($A13="","",IFERROR(IF(INDIRECT("'"&$A13&"'!I9")="","",INDIRECT("'"&$A13&"'!I9")+0),"Tab not found")) | N13: =IF($A13="","",IFERROR(IF(INDIRECT("'"&$A13&"'!I10")="","",INDIRECT("'"&$A13&"'!I10")+0),"Tab not found"))
B14: =IF($A14="","",IFERROR(INDIRECT("'"&$A14&"'!C4")&"","Tab not found")) | C14: =IF($A14="","",IFERROR(INDIRECT("'"&$A14&"'!C5")&"","Tab not found")) | D14: =IF($A14="","",IFERROR(INDIRECT("'"&$A14&"'!C6")&"","Tab not found")) | E14: =IF($A14="","",IFERROR(INDIRECT("'"&$A14&"'!C7")&"","Tab not found")) | F14: =IF($A14="","",IFERROR(IF(INDIRECT("'"&$A14&"'!C8")="","",INDIRECT("'"&$A14&"'!C8")),"Tab not found")) | G14: =IF($A14="","",IFERROR(IF(INDIRECT("'"&$A14&"'!C9")="","",INDIRECT("'"&$A14&"'!C9")),"Tab not found")) | H14: =IF($A14="","",IFERROR(INDIRECT("'"&$A14&"'!C10")&"","Tab not found")) | I14: =IF($A14="","",IFERROR(IF(INDIRECT("'"&$A14&"'!I3")="","",INDIRECT("'"&$A14&"'!I3")+0),"Tab not found")) | J14: =IF($A14="","",IFERROR(IF(INDIRECT("'"&$A14&"'!I4")="","",INDIRECT("'"&$A14&"'!I4")+0),"Tab not found")) | K14: =IF($A14="","",IFERROR(IF(INDIRECT("'"&$A14&"'!I5")="","",INDIRECT("'"&$A14&"'!I5")+0),"Tab not found")) | L14: =IF($A14="","",IFERROR(IF(INDIRECT("'"&$A14&"'!I7")="","",INDIRECT("'"&$A14&"'!I7")+0),"Tab not found")) | M14: =IF($A14="","",IFERROR(IF(INDIRECT("'"&$A14&"'!I9")="","",INDIRECT("'"&$A14&"'!I9")+0),"Tab not found")) | N14: =IF($A14="","",IFERROR(IF(INDIRECT("'"&$A14&"'!I10")="","",INDIRECT("'"&$A14&"'!I10")+0),"Tab not found"))
B15: =IF($A15="","",IFERROR(INDIRECT("'"&$A15&"'!C4")&"","Tab not found")) | C15: =IF($A15="","",IFERROR(INDIRECT("'"&$A15&"'!C5")&"","Tab not found")) | D15: =IF($A15="","",IFERROR(INDIRECT("'"&$A15&"'!C6")&"","Tab not found")) | E15: =IF($A15="","",IFERROR(INDIRECT("'"&$A15&"'!C7")&"","Tab not found")) | F15: =IF($A15="","",IFERROR(IF(INDIRECT("'"&$A15&"'!C8")="","",INDIRECT("'"&$A15&"'!C8")),"Tab not found")) | G15: =IF($A15="","",IFERROR(IF(INDIRECT("'"&$A15&"'!C9")="","",INDIRECT("'"&$A15&"'!C9")),"Tab not found")) | H15: =IF($A15="","",IFERROR(INDIRECT("'"&$A15&"'!C10")&"","Tab not found")) | I15: =IF($A15="","",IFERROR(IF(INDIRECT("'"&$A15&"'!I3")="","",INDIRECT("'"&$A15&"'!I3")+0),"Tab not found")) | J15: =IF($A15="","",IFERROR(IF(INDIRECT("'"&$A15&"'!I4")="","",INDIRECT("'"&$A15&"'!I4")+0),"Tab not found")) | K15: =IF($A15="","",IFERROR(IF(INDIRECT("'"&$A15&"'!I5")="","",INDIRECT("'"&$A15&"'!I5")+0),"Tab not found")) | L15: =IF($A15="","",IFERROR(IF(INDIRECT("'"&$A15&"'!I7")="","",INDIRECT("'"&$A15&"'!I7")+0),"Tab not found")) | M15: =IF($A15="","",IFERROR(IF(INDIRECT("'"&$A15&"'!I9")="","",INDIRECT("'"&$A15&"'!I9")+0),"Tab not found")) | N15: =IF($A15="","",IFERROR(IF(INDIRECT("'"&$A15&"'!I10")="","",INDIRECT("'"&$A15&"'!I10")+0),"Tab not found"))
B16: =IF($A16="","",IFERROR(INDIRECT("'"&$A16&"'!C4")&"","Tab not found")) | C16: =IF($A16="","",IFERROR(INDIRECT("'"&$A16&"'!C5")&"","Tab not found")) | D16: =IF($A16="","",IFERROR(INDIRECT("'"&$A16&"'!C6")&"","Tab not found")) | E16: =IF($A16="","",IFERROR(INDIRECT("'"&$A16&"'!C7")&"","Tab not found")) | F16: =IF($A16="","",IFERROR(IF(INDIRECT("'"&$A16&"'!C8")="","",INDIRECT("'"&$A16&"'!C8")),"Tab not found")) | G16: =IF($A16="","",IFERROR(IF(INDIRECT("'"&$A16&"'!C9")="","",INDIRECT("'"&$A16&"'!C9")),"Tab not found")) | H16: =IF($A16="","",IFERROR(INDIRECT("'"&$A16&"'!C10")&"","Tab not found")) | I16: =IF($A16="","",IFERROR(IF(INDIRECT("'"&$A16&"'!I3")="","",INDIRECT("'"&$A16&"'!I3")+0),"Tab not found")) | J16: =IF($A16="","",IFERROR(IF(INDIRECT("'"&$A16&"'!I4")="","",INDIRECT("'"&$A16&"'!I4")+0),"Tab not found")) | K16: =IF($A16="","",IFERROR(IF(INDIRECT("'"&$A16&"'!I5")="","",INDIRECT("'"&$A16&"'!I5")+0),"Tab not found")) | L16: =IF($A16="","",IFERROR(IF(INDIRECT("'"&$A16&"'!I7")="","",INDIRECT("'"&$A16&"'!I7")+0),"Tab not found")) | M16: =IF($A16="","",IFERROR(IF(INDIRECT("'"&$A16&"'!I9")="","",INDIRECT("'"&$A16&"'!I9")+0),"Tab not found")) | N16: =IF($A16="","",IFERROR(IF(INDIRECT("'"&$A16&"'!I10")="","",INDIRECT("'"&$A16&"'!I10")+0),"Tab not found"))
B17: =IF($A17="","",IFERROR(INDIRECT("'"&$A17&"'!C4")&"","Tab not found")) | C17: =IF($A17="","",IFERROR(INDIRECT("'"&$A17&"'!C5")&"","Tab not found")) | D17: =IF($A17="","",IFERROR(INDIRECT("'"&$A17&"'!C6")&"","Tab not found")) | E17: =IF($A17="","",IFERROR(INDIRECT("'"&$A17&"'!C7")&"","Tab not found")) | F17: =IF($A17="","",IFERROR(IF(INDIRECT("'"&$A17&"'!C8")="","",INDIRECT("'"&$A17&"'!C8")),"Tab not found")) | G17: =IF($A17="","",IFERROR(IF(INDIRECT("'"&$A17&"'!C9")="","",INDIRECT("'"&$A17&"'!C9")),"Tab not found")) | H17: =IF($A17="","",IFERROR(INDIRECT("'"&$A17&"'!C10")&"","Tab not found")) | I17: =IF($A17="","",IFERROR(IF(INDIRECT("'"&$A17&"'!I3")="","",INDIRECT("'"&$A17&"'!I3")+0),"Tab not found")) | J17: =IF($A17="","",IFERROR(IF(INDIRECT("'"&$A17&"'!I4")="","",INDIRECT("'"&$A17&"'!I4")+0),"Tab not found")) | K17: =IF($A17="","",IFERROR(IF(INDIRECT("'"&$A17&"'!I5")="","",INDIRECT("'"&$A17&"'!I5")+0),"Tab not found")) | L17: =IF($A17="","",IFERROR(IF(INDIRECT("'"&$A17&"'!I7")="","",INDIRECT("'"&$A17&"'!I7")+0),"Tab not found")) | M17: =IF($A17="","",IFERROR(IF(INDIRECT("'"&$A17&"'!I9")="","",INDIRECT("'"&$A17&"'!I9")+0),"Tab not found")) | N17: =IF($A17="","",IFERROR(IF(INDIRECT("'"&$A17&"'!I10")="","",INDIRECT("'"&$A17&"'!I10")+0),"Tab not found"))
... B104: =IF($A104="","",IFERROR(INDIRECT("'"&$A104&"'!C4")&"","Tab not found")) | C104: =IF($A104="","",IFERROR(INDIRECT("'"&$A104&"'!C5")&"","Tab not found")) | D104: =IF($A104="","",IFERROR(INDIRECT("'"&$A104&"'!C6")&"","Tab not found")) | E104: =IF($A104="","",IFERROR(INDIRECT("'"&$A104&"'!C7")&"","Tab not found")) | F104: =IF($A104="","",IFERROR(IF(INDIRECT("'"&$A104&"'!C8")="","",INDIRECT("'"&$A104&"'!C8")),"Tab not found")) | G104: =IF($A104="","",IFERROR(IF(INDIRECT("'"&$A104&"'!C9")="","",INDIRECT("'"&$A104&"'!C9")),"Tab not found")) | H104: =IF($A104="","",IFERROR(INDIRECT("'"&$A104&"'!C10")&"","Tab not found")) | I104: =IF($A104="","",IFERROR(IF(INDIRECT("'"&$A104&"'!I3")="","",INDIRECT("'"&$A104&"'!I3")+0),"Tab not found")) | J104: =IF($A104="","",IFERROR(IF(INDIRECT("'"&$A104&"'!I4")="","",INDIRECT("'"&$A104&"'!I4")+0),"Tab not found")) | K104: =IF($A104="","",IFERROR(IF(INDIRECT("'"&$A104&"'!I5")="","",INDIRECT("'"&$A104&"'!I5")+0),"Tab not found")) | L104: =IF($A104="","",IFERROR(IF(INDIRECT("'"&$A104&"'!I7")="","",INDIRECT("'"&$A104&"'!I7")+0),"Tab not found")) | M104: =IF($A104="","",IFERROR(IF(INDIRECT("'"&$A104&"'!I9")="","",INDIRECT("'"&$A104&"'!I9")+0),"Tab not found")) | N104: =IF($A104="","",IFERROR(IF(INDIRECT("'"&$A104&"'!I10")="","",INDIRECT("'"&$A104&"'!I10")+0),"Tab not found"))

Sheet RFI-001
A1: =IF(C3="","RFI Activity (new - fill in the yellow cells)",C3&" | "&C6) -> RFI-001 | EXAMPLE - BESS equipment RFI (repurpose or delete)
A2: Yellow = enter data. Grey = formula, do not overwrite (except key item headers in row 13, which you may type over). Rename this tab to match the RFI ID, then add the ID to the RFI Register.
B3: RFI ID | C3: RFI-001 | H3: Vendors invited | I3: =COUNTA($A$15:$A$64) -> 10
B4: Project | C4: Project A (placeholder - rename) | H4: RFIs sent | I4: =COUNTIFS($A$15:$A$64,"<>",$F$15:$F$64,"<>Not Sent",$F$15:$F$64,"<>") -> 0
B5: Vendor Type | C5: BESS Equipment | H5: Responses received | I5: =COUNTIF($F$15:$F$64,"Response Received")+COUNTIF($F$15:$F$64,"Under Review")+COUNTIF($F$15:$F$64,"Complete") -> 0
B6: RFI Title / Scope | C6: EXAMPLE - BESS equipment RFI (repurpose or delete) | H6: Declined / no response | I6: =COUNTIF($F$15:$F$64,"Declined")+COUNTIF($F$15:$F$64,"No Response") -> 0
B7: RFI Owner | C7: Jason Knedlhans | H7: Actions overdue | I7: =COUNTIF($AH$15:$AH$64,"OVERDUE") -> 0
B8: Issue Date | H8: Key items: Review / Risk | I8: =COUNTIF($L$15:$L$64,"Review / Risk")+COUNTIF($N$15:$N$64,"Review / Risk")+COUNTIF($P$15:$P$64,"Review / Risk")+COUNTIF($R$15:$R$64,"Review / Risk")+COUNTIF($T$15:$T$64,"Review / Risk")+COUNTIF($V$15:$V$64,"Review / Risk")+COUNTIF($X$15:$X$64,"Review / Risk")+COUNTIF($Z$15:$Z$64,"Review / Risk")+COUNTIF($AB$15:$AB$64,"Review / Risk")+COUNTIF($AD$15:$AD$64,"Review / Risk") -> 9
B9: Response Due | H9: Key items: Fails | I9: =COUNTIF($L$15:$L$64,"Fails")+COUNTIF($N$15:$N$64,"Fails")+COUNTIF($P$15:$P$64,"Fails")+COUNTIF($R$15:$R$64,"Fails")+COUNTIF($T$15:$T$64,"Fails")+COUNTIF($V$15:$V$64,"Fails")+COUNTIF($X$15:$X$64,"Fails")+COUNTIF($Z$15:$Z$64,"Fails")+COUNTIF($AB$15:$AB$64,"Fails")+COUNTIF($AD$15:$AD$64,"Fails") -> 0
B10: Activity Status | C10: Planning | H10: Days to response due | I10: =IF(C9="","",C9-TODAY())
A12: VENDOR & CONTACT (contacts pull from Vendors tab) | F12: RFI | K12: ="KEY ITEMS - "&IF($C$5="","pick a Vendor Type in C5",UPPER($C$5)) -> KEY ITEMS - BESS EQUIPMENT | AE12: NEXT ACTION
A13: Vendor | B13: Vendor ID | C13: Contact Name | D13: Contact Email | E13: Contact Phone | F13: RFI Status | G13: Date Sent | H13: Last Contact | I13: Response Date | J13: Qualification Status | K13: =IF($C$5="","Key item 1",IFERROR(IF(INDEX('Key Items'!$B$5:$O$14,1,MATCH($C$5,'Key Items'!$B$4:$O$4,0))="","Key item 1 (spare - type a name)",INDEX('Key Items'!$B$5:$O$14,1,MATCH($C$5,'Key Items'!$B$4:$O$4,0))),"Key item 1")) -> Lead time (weeks ARO) | M13: =IF($C$5="","Key item 2",IFERROR(IF(INDEX('Key Items'!$B$5:$O$14,2,MATCH($C$5,'Key Items'!$B$4:$O$4,0))="","Key item 2 (spare - type a name)",INDEX('Key Items'!$B$5:$O$14,2,MATCH($C$5,'Key Items'!$B$4:$O$4,0))),"Key item 2")) -> FEOC compliance | O13: =IF($C$5="","Key item 3",IFERROR(IF(INDEX('Key Items'!$B$5:$O$14,3,MATCH($C$5,'Key Items'!$B$4:$O$4,0))="","Key item 3 (spare - type a name)",INDEX('Key Items'!$B$5:$O$14,3,MATCH($C$5,'Key Items'!$B$4:$O$4,0))),"Key item 3")) -> Cell chemistry & cell / module origin | Q13: =IF($C$5="","Key item 4",IFERROR(IF(INDEX('Key Items'!$B$5:$O$14,4,MATCH($C$5,'Key Items'!$B$4:$O$4,0))="","Key item 4 (spare - type a name)",INDEX('Key Items'!$B$5:$O$14,4,MATCH($C$5,'Key Items'!$B$4:$O$4,0))),"Key item 4")) -> Certifications (UL 9540, UL 9540A, NFPA 855) | S13: =IF($C$5="","Key item 5",IFERROR(IF(INDEX('Key Items'!$B$5:$O$14,5,MATCH($C$5,'Key Items'!$B$4:$O$4,0))="","Key item 5 (spare - type a name)",INDEX('Key Items'!$B$5:$O$14,5,MATCH($C$5,'Key Items'!$B$4:$O$4,0))),"Key item 5")) -> Warranty & performance guarantee | U13: =IF($C$5="","Key item 6",IFERROR(IF(INDEX('Key Items'!$B$5:$O$14,6,MATCH($C$5,'Key Items'!$B$4:$O$4,0))="","Key item 6 (spare - type a name)",INDEX('Key Items'!$B$5:$O$14,6,MATCH($C$5,'Key Items'!$B$4:$O$4,0))),"Key item 6")) -> Domestic content (ITC adder) | W13: =IF($C$5="","Key item 7",IFERROR(IF(INDEX('Key Items'!$B$5:$O$14,7,MATCH($C$5,'Key Items'!$B$4:$O$4,0))="","Key item 7 (spare - type a name)",INDEX('Key Items'!$B$5:$O$14,7,MATCH($C$5,'Key Items'!$B$4:$O$4,0))),"Key item 7")) -> Bankability / financial strength | Y13: =IF($C$5="","Key item 8",IFERROR(IF(INDEX('Key Items'!$B$5:$O$14,8,MATCH($C$5,'Key Items'!$B$4:$O$4,0))="","Key item 8 (spare - type a name)",INDEX('Key Items'!$B$5:$O$14,8,MATCH($C$5,'Key Items'!$B$4:$O$4,0))),"Key item 8")) -> Key item 8 (spare - type a name) | AA13: =IF($C$5="","Key item 9",IFERROR(IF(INDEX('Key Items'!$B$5:$O$14,9,MATCH($C$5,'Key Items'!$B$4:$O$4,0))="","Key item 9 (spare - type a name)",INDEX('Key Items'!$B$5:$O$14,9,MATCH($C$5,'Key Items'!$B$4:$O$4,0))),"Key item 9")) -> Key item 9 (spare - type a name) | AC13: =IF($C$5="","Key item 10",IFERROR(IF(INDEX('Key Items'!$B$5:$O$14,10,MATCH($C$5,'Key Items'!$B$4:$O$4,0))="","Key item 10 (spare - type a name)",INDEX('Key Items'!$B$5:$O$14,10,MATCH($C$5,'Key Items'!$B$4:$O$4,0))),"Key item 10")) -> Key item 10 (spare - type a name) | AE13: Next Action | AF13: Next Action Owner | AG13: Next Action Date | AH13: Action Flag | AI13: Notes
K14: Response / notes | L14: Rating | M14: Response / notes | N14: Rating | O14: Response / notes | P14: Rating | Q14: Response / notes | R14: Rating | S14: Response / notes | T14: Rating | U14: Response / notes | V14: Rating | W14: Response / notes | X14: Rating | Y14: Response / notes | Z14: Rating | AA14: Response / notes | AB14: Rating | AC14: Response / notes | AD14: Rating
A15: Tesla (Tesla Energy) | B15: =IF($A15="","",IFERROR(INDEX(Vendors!$A$5:$A$400,MATCH($A15,Vendors!$B$5:$B$400,0)),"Not in Vendors tab")) -> BESS-001 | C15: =IF($A15="","",IFERROR(INDEX(Vendors!$H$5:$H$400,MATCH($A15,Vendors!$B$5:$B$400,0))&"","")) | D15: =IF($A15="","",IFERROR(INDEX(Vendors!$J$5:$J$400,MATCH($A15,Vendors!$B$5:$B$400,0))&"","")) | E15: =IF($A15="","",IFERROR(IF(INDEX(Vendors!$K$5:$K$400,MATCH($A15,Vendors!$B$5:$B$400,0))&""="",INDEX(Vendors!$F$5:$F$400,MATCH($A15,Vendors!$B$5:$B$400,0))&"",INDEX(Vendors!$K$5:$K$400,MATCH($A15,Vendors!$B$5:$B$400,0))&""),"")) | F15: Not Sent | J15: Discovery | M15: Flagged FEOC Review in vendor landscape - confirm ownership / origin in RFI | N15: Review / Risk | AE15: Identify RFI contact | AF15: Jason Knedlhans | AH15: =IF(OR($A15="",AG15=""),"",IF(OR(F15="Complete",F15="Declined",F15="No Response"),"",IF(AG15<TODAY(),"OVERDUE",IF(AG15-TODAY()<=7,"Due 7d",""))))
A16: Fluence Energy | B16: =IF($A16="","",IFERROR(INDEX(Vendors!$A$5:$A$400,MATCH($A16,Vendors!$B$5:$B$400,0)),"Not in Vendors tab")) -> BESS-002 | C16: =IF($A16="","",IFERROR(INDEX(Vendors!$H$5:$H$400,MATCH($A16,Vendors!$B$5:$B$400,0))&"","")) | D16: =IF($A16="","",IFERROR(INDEX(Vendors!$J$5:$J$400,MATCH($A16,Vendors!$B$5:$B$400,0))&"","")) | E16: =IF($A16="","",IFERROR(IF(INDEX(Vendors!$K$5:$K$400,MATCH($A16,Vendors!$B$5:$B$400,0))&""="",INDEX(Vendors!$F$5:$F$400,MATCH($A16,Vendors!$B$5:$B$400,0))&"",INDEX(Vendors!$K$5:$K$400,MATCH($A16,Vendors!$B$5:$B$400,0))&""),"")) | F16: Not Sent | J16: Discovery | M16: Flagged FEOC Review in vendor landscape - confirm ownership / origin in RFI | N16: Review / Risk | AE16: Identify RFI contact | AF16: Jason Knedlhans | AH16: =IF(OR($A16="",AG16=""),"",IF(OR(F16="Complete",F16="Declined",F16="No Response"),"",IF(AG16<TODAY(),"OVERDUE",IF(AG16-TODAY()<=7,"Due 7d",""))))
A17: Sungrow | B17: =IF($A17="","",IFERROR(INDEX(Vendors!$A$5:$A$400,MATCH($A17,Vendors!$B$5:$B$400,0)),"Not in Vendors tab")) -> BESS-003 | C17: =IF($A17="","",IFERROR(INDEX(Vendors!$H$5:$H$400,MATCH($A17,Vendors!$B$5:$B$400,0))&"","")) | D17: =IF($A17="","",IFERROR(INDEX(Vendors!$J$5:$J$400,MATCH($A17,Vendors!$B$5:$B$400,0))&"","")) | E17: =IF($A17="","",IFERROR(IF(INDEX(Vendors!$K$5:$K$400,MATCH($A17,Vendors!$B$5:$B$400,0))&""="",INDEX(Vendors!$F$5:$F$400,MATCH($A17,Vendors!$B$5:$B$400,0))&"",INDEX(Vendors!$K$5:$K$400,MATCH($A17,Vendors!$B$5:$B$400,0))&""),"")) -> +1 833 747 6937 | F17: Not Sent | J17: Discovery | M17: Flagged FEOC Review in vendor landscape - confirm ownership / origin in RFI | N17: Review / Risk | AE17: Identify RFI contact | AF17: Jason Knedlhans | AH17: =IF(OR($A17="",AG17=""),"",IF(OR(F17="Complete",F17="Declined",F17="No Response"),"",IF(AG17<TODAY(),"OVERDUE",IF(AG17-TODAY()<=7,"Due 7d",""))))
A18: LG Energy Solution Vertech | B18: =IF($A18="","",IFERROR(INDEX(Vendors!$A$5:$A$400,MATCH($A18,Vendors!$B$5:$B$400,0)),"Not in Vendors tab")) -> BESS-004 | C18: =IF($A18="","",IFERROR(INDEX(Vendors!$H$5:$H$400,MATCH($A18,Vendors!$B$5:$B$400,0))&"","")) | D18: =IF($A18="","",IFERROR(INDEX(Vendors!$J$5:$J$400,MATCH($A18,Vendors!$B$5:$B$400,0))&"","")) | E18: =IF($A18="","",IFERROR(IF(INDEX(Vendors!$K$5:$K$400,MATCH($A18,Vendors!$B$5:$B$400,0))&""="",INDEX(Vendors!$F$5:$F$400,MATCH($A18,Vendors!$B$5:$B$400,0))&"",INDEX(Vendors!$K$5:$K$400,MATCH($A18,Vendors!$B$5:$B$400,0))&""),"")) | F18: Not Sent | J18: Discovery | M18: Flagged FEOC Review in vendor landscape - confirm ownership / origin in RFI | N18: Review / Risk | AE18: Identify RFI contact | AF18: Jason Knedlhans | AH18: =IF(OR($A18="",AG18=""),"",IF(OR(F18="Complete",F18="Declined",F18="No Response"),"",IF(AG18<TODAY(),"OVERDUE",IF(AG18-TODAY()<=7,"Due 7d",""))))
A19: Samsung SDI | B19: =IF($A19="","",IFERROR(INDEX(Vendors!$A$5:$A$400,MATCH($A19,Vendors!$B$5:$B$400,0)),"Not in Vendors tab")) -> BESS-005 | C19: =IF($A19="","",IFERROR(INDEX(Vendors!$H$5:$H$400,MATCH($A19,Vendors!$B$5:$B$400,0))&"","")) | D19: =IF($A19="","",IFERROR(INDEX(Vendors!$J$5:$J$400,MATCH($A19,Vendors!$B$5:$B$400,0))&"","")) | E19: =IF($A19="","",IFERROR(IF(INDEX(Vendors!$K$5:$K$400,MATCH($A19,Vendors!$B$5:$B$400,0))&""="",INDEX(Vendors!$F$5:$F$400,MATCH($A19,Vendors!$B$5:$B$400,0))&"",INDEX(Vendors!$K$5:$K$400,MATCH($A19,Vendors!$B$5:$B$400,0))&""),"")) | F19: Not Sent | J19: Discovery | AE19: Identify RFI contact | AF19: Jason Knedlhans | AH19: =IF(OR($A19="",AG19=""),"",IF(OR(F19="Complete",F19="Declined",F19="No Response"),"",IF(AG19<TODAY(),"OVERDUE",IF(AG19-TODAY()<=7,"Due 7d",""))))
A20: Wärtsilä Energy Storage | B20: =IF($A20="","",IFERROR(INDEX(Vendors!$A$5:$A$400,MATCH($A20,Vendors!$B$5:$B$400,0)),"Not in Vendors tab")) -> BESS-006 | C20: =IF($A20="","",IFERROR(INDEX(Vendors!$H$5:$H$400,MATCH($A20,Vendors!$B$5:$B$400,0))&"","")) | D20: =IF($A20="","",IFERROR(INDEX(Vendors!$J$5:$J$400,MATCH($A20,Vendors!$B$5:$B$400,0))&"","")) | E20: =IF($A20="","",IFERROR(IF(INDEX(Vendors!$K$5:$K$400,MATCH($A20,Vendors!$B$5:$B$400,0))&""="",INDEX(Vendors!$F$5:$F$400,MATCH($A20,Vendors!$B$5:$B$400,0))&"",INDEX(Vendors!$K$5:$K$400,MATCH($A20,Vendors!$B$5:$B$400,0))&""),"")) -> +1 281 233 6200 | F20: Not Sent | J20: Discovery | M20: Flagged FEOC Review in vendor landscape - confirm ownership / origin in RFI | N20: Review / Risk | AE20: Identify RFI contact | AF20: Jason Knedlhans | AH20: =IF(OR($A20="",AG20=""),"",IF(OR(F20="Complete",F20="Declined",F20="No Response"),"",IF(AG20<TODAY(),"OVERDUE",IF(AG20-TODAY()<=7,"Due 7d",""))))
A21: FlexGen Power Systems | B21: =IF($A21="","",IFERROR(INDEX(Vendors!$A$5:$A$400,MATCH($A21,Vendors!$B$5:$B$400,0)),"Not in Vendors tab")) -> BESS-007 | C21: =IF($A21="","",IFERROR(INDEX(Vendors!$H$5:$H$400,MATCH($A21,Vendors!$B$5:$B$400,0))&"","")) | D21: =IF($A21="","",IFERROR(INDEX(Vendors!$J$5:$J$400,MATCH($A21,Vendors!$B$5:$B$400,0))&"","")) | E21: =IF($A21="","",IFERROR(IF(INDEX(Vendors!$K$5:$K$400,MATCH($A21,Vendors!$B$5:$B$400,0))&""="",INDEX(Vendors!$F$5:$F$400,MATCH($A21,Vendors!$B$5:$B$400,0))&"",INDEX(Vendors!$K$5:$K$400,MATCH($A21,Vendors!$B$5:$B$400,0))&""),"")) -> 855-327-5674 | F21: Not Sent | J21: Discovery | M21: Flagged FEOC Review in vendor landscape - confirm ownership / origin in RFI | N21: Review / Risk | AE21: Identify RFI contact | AF21: Jason Knedlhans | AH21: =IF(OR($A21="",AG21=""),"",IF(OR(F21="Complete",F21="Declined",F21="No Response"),"",IF(AG21<TODAY(),"OVERDUE",IF(AG21-TODAY()<=7,"Due 7d",""))))
A22: Hithium | B22: =IF($A22="","",IFERROR(INDEX(Vendors!$A$5:$A$400,MATCH($A22,Vendors!$B$5:$B$400,0)),"Not in Vendors tab")) -> BESS-008 | C22: =IF($A22="","",IFERROR(INDEX(Vendors!$H$5:$H$400,MATCH($A22,Vendors!$B$5:$B$400,0))&"","")) | D22: =IF($A22="","",IFERROR(INDEX(Vendors!$J$5:$J$400,MATCH($A22,Vendors!$B$5:$B$400,0))&"","")) | E22: =IF($A22="","",IFERROR(IF(INDEX(Vendors!$K$5:$K$400,MATCH($A22,Vendors!$B$5:$B$400,0))&""="",INDEX(Vendors!$F$5:$F$400,MATCH($A22,Vendors!$B$5:$B$400,0))&"",INDEX(Vendors!$K$5:$K$400,MATCH($A22,Vendors!$B$5:$B$400,0))&""),"")) | F22: Not Sent | J22: Discovery | M22: Flagged FEOC Review in vendor landscape - confirm ownership / origin in RFI | N22: Review / Risk | AE22: Identify RFI contact | AF22: Jason Knedlhans | AH22: =IF(OR($A22="",AG22=""),"",IF(OR(F22="Complete",F22="Declined",F22="No Response"),"",IF(AG22<TODAY(),"OVERDUE",IF(AG22-TODAY()<=7,"Due 7d",""))))
A23: Canadian Solar e-STORAGE | B23: =IF($A23="","",IFERROR(INDEX(Vendors!$A$5:$A$400,MATCH($A23,Vendors!$B$5:$B$400,0)),"Not in Vendors tab")) -> BESS-009 | C23: =IF($A23="","",IFERROR(INDEX(Vendors!$H$5:$H$400,MATCH($A23,Vendors!$B$5:$B$400,0))&"","")) | D23: =IF($A23="","",IFERROR(INDEX(Vendors!$J$5:$J$400,MATCH($A23,Vendors!$B$5:$B$400,0))&"","")) | E23: =IF($A23="","",IFERROR(IF(INDEX(Vendors!$K$5:$K$400,MATCH($A23,Vendors!$B$5:$B$400,0))&""="",INDEX(Vendors!$F$5:$F$400,MATCH($A23,Vendors!$B$5:$B$400,0))&"",INDEX(Vendors!$K$5:$K$400,MATCH($A23,Vendors!$B$5:$B$400,0))&""),"")) | F23: Not Sent | J23: Discovery | M23: Flagged FEOC Review in vendor landscape - confirm ownership / origin in RFI | N23: Review / Risk | AE23: Identify RFI contact | AF23: Jason Knedlhans | AH23: =IF(OR($A23="",AG23=""),"",IF(OR(F23="Complete",F23="Declined",F23="No Response"),"",IF(AG23<TODAY(),"OVERDUE",IF(AG23-TODAY()<=7,"Due 7d",""))))
A24: Prevalon Energy (now Nextpower) | B24: =IF($A24="","",IFERROR(INDEX(Vendors!$A$5:$A$400,MATCH($A24,Vendors!$B$5:$B$400,0)),"Not in Vendors tab")) -> BESS-010 | C24: =IF($A24="","",IFERROR(INDEX(Vendors!$H$5:$H$400,MATCH($A24,Vendors!$B$5:$B$400,0))&"","")) | D24: =IF($A24="","",IFERROR(INDEX(Vendors!$J$5:$J$400,MATCH($A24,Vendors!$B$5:$B$400,0))&"","")) | E24: =IF($A24="","",IFERROR(IF(INDEX(Vendors!$K$5:$K$400,MATCH($A24,Vendors!$B$5:$B$400,0))&""="",INDEX(Vendors!$F$5:$F$400,MATCH($A24,Vendors!$B$5:$B$400,0))&"",INDEX(Vendors!$K$5:$K$400,MATCH($A24,Vendors!$B$5:$B$400,0))&""),"")) | F24: Not Sent | J24: Discovery | M24: Flagged FEOC Review in vendor landscape - confirm ownership / origin in RFI | N24: Review / Risk | AE24: Identify RFI contact | AF24: Jason Knedlhans | AH24: =IF(OR($A24="",AG24=""),"",IF(OR(F24="Complete",F24="Declined",F24="No Response"),"",IF(AG24<TODAY(),"OVERDUE",IF(AG24-TODAY()<=7,"Due 7d",""))))
B25: =IF($A25="","",IFERROR(INDEX(Vendors!$A$5:$A$400,MATCH($A25,Vendors!$B$5:$B$400,0)),"Not in Vendors tab")) | C25: =IF($A25="","",IFERROR(INDEX(Vendors!$H$5:$H$400,MATCH($A25,Vendors!$B$5:$B$400,0))&"","")) | D25: =IF($A25="","",IFERROR(INDEX(Vendors!$J$5:$J$400,MATCH($A25,Vendors!$B$5:$B$400,0))&"","")) | E25: =IF($A25="","",IFERROR(IF(INDEX(Vendors!$K$5:$K$400,MATCH($A25,Vendors!$B$5:$B$400,0))&""="",INDEX(Vendors!$F$5:$F$400,MATCH($A25,Vendors!$B$5:$B$400,0))&"",INDEX(Vendors!$K$5:$K$400,MATCH($A25,Vendors!$B$5:$B$400,0))&""),"")) | AH25: =IF(OR($A25="",AG25=""),"",IF(OR(F25="Complete",F25="Declined",F25="No Response"),"",IF(AG25<TODAY(),"OVERDUE",IF(AG25-TODAY()<=7,"Due 7d",""))))
B26: =IF($A26="","",IFERROR(INDEX(Vendors!$A$5:$A$400,MATCH($A26,Vendors!$B$5:$B$400,0)),"Not in Vendors tab")) | C26: =IF($A26="","",IFERROR(INDEX(Vendors!$H$5:$H$400,MATCH($A26,Vendors!$B$5:$B$400,0))&"","")) | D26: =IF($A26="","",IFERROR(INDEX(Vendors!$J$5:$J$400,MATCH($A26,Vendors!$B$5:$B$400,0))&"","")) | E26: =IF($A26="","",IFERROR(IF(INDEX(Vendors!$K$5:$K$400,MATCH($A26,Vendors!$B$5:$B$400,0))&""="",INDEX(Vendors!$F$5:$F$400,MATCH($A26,Vendors!$B$5:$B$400,0))&"",INDEX(Vendors!$K$5:$K$400,MATCH($A26,Vendors!$B$5:$B$400,0))&""),"")) | AH26: =IF(OR($A26="",AG26=""),"",IF(OR(F26="Complete",F26="Declined",F26="No Response"),"",IF(AG26<TODAY(),"OVERDUE",IF(AG26-TODAY()<=7,"Due 7d",""))))
B27: =IF($A27="","",IFERROR(INDEX(Vendors!$A$5:$A$400,MATCH($A27,Vendors!$B$5:$B$400,0)),"Not in Vendors tab")) | C27: =IF($A27="","",IFERROR(INDEX(Vendors!$H$5:$H$400,MATCH($A27,Vendors!$B$5:$B$400,0))&"","")) | D27: =IF($A27="","",IFERROR(INDEX(Vendors!$J$5:$J$400,MATCH($A27,Vendors!$B$5:$B$400,0))&"","")) | E27: =IF($A27="","",IFERROR(IF(INDEX(Vendors!$K$5:$K$400,MATCH($A27,Vendors!$B$5:$B$400,0))&""="",INDEX(Vendors!$F$5:$F$400,MATCH($A27,Vendors!$B$5:$B$400,0))&"",INDEX(Vendors!$K$5:$K$400,MATCH($A27,Vendors!$B$5:$B$400,0))&""),"")) | AH27: =IF(OR($A27="",AG27=""),"",IF(OR(F27="Complete",F27="Declined",F27="No Response"),"",IF(AG27<TODAY(),"OVERDUE",IF(AG27-TODAY()<=7,"Due 7d",""))))
B28: =IF($A28="","",IFERROR(INDEX(Vendors!$A$5:$A$400,MATCH($A28,Vendors!$B$5:$B$400,0)),"Not in Vendors tab")) | C28: =IF($A28="","",IFERROR(INDEX(Vendors!$H$5:$H$400,MATCH($A28,Vendors!$B$5:$B$400,0))&"","")) | D28: =IF($A28="","",IFERROR(INDEX(Vendors!$J$5:$J$400,MATCH($A28,Vendors!$B$5:$B$400,0))&"","")) | E28: =IF($A28="","",IFERROR(IF(INDEX(Vendors!$K$5:$K$400,MATCH($A28,Vendors!$B$5:$B$400,0))&""="",INDEX(Vendors!$F$5:$F$400,MATCH($A28,Vendors!$B$5:$B$400,0))&"",INDEX(Vendors!$K$5:$K$400,MATCH($A28,Vendors!$B$5:$B$400,0))&""),"")) | AH28: =IF(OR($A28="",AG28=""),"",IF(OR(F28="Complete",F28="Declined",F28="No Response"),"",IF(AG28<TODAY(),"OVERDUE",IF(AG28-TODAY()<=7,"Due 7d",""))))
B29: =IF($A29="","",IFERROR(INDEX(Vendors!$A$5:$A$400,MATCH($A29,Vendors!$B$5:$B$400,0)),"Not in Vendors tab")) | C29: =IF($A29="","",IFERROR(INDEX(Vendors!$H$5:$H$400,MATCH($A29,Vendors!$B$5:$B$400,0))&"","")) | D29: =IF($A29="","",IFERROR(INDEX(Vendors!$J$5:$J$400,MATCH($A29,Vendors!$B$5:$B$400,0))&"","")) | E29: =IF($A29="","",IFERROR(IF(INDEX(Vendors!$K$5:$K$400,MATCH($A29,Vendors!$B$5:$B$400,0))&""="",INDEX(Vendors!$F$5:$F$400,MATCH($A29,Vendors!$B$5:$B$400,0))&"",INDEX(Vendors!$K$5:$K$400,MATCH($A29,Vendors!$B$5:$B$400,0))&""),"")) | AH29: =IF(OR($A29="",AG29=""),"",IF(OR(F29="Complete",F29="Declined",F29="No Response"),"",IF(AG29<TODAY(),"OVERDUE",IF(AG29-TODAY()<=7,"Due 7d",""))))
