Workbook
Name lst_fin: Lists!$C$2:$C$5
Name lst_rfx: Lists!$B$2:$B$9
Name lst_scr: Lists!$D$2:$D$6
Name lst_status: Lists!$A$2:$A$7
Name lst_ver: Lists!$E$2:$E$3

Sheet Read Me
A1: Vendor Landscape Tracker
A2: Agentic — Procurement | v01 | 2026-10-05 | Owner: Jason Knedlhans | Classification: Internal
A4: PURPOSE
A5: What | B5: Landscape of candidate vendors for each Agentic procurement scope; feeds prequalification, RFI/RFP/RFQ invitations and the AVL (Objectives 1 and 4).
A6: Structure | B6: Dashboard (live counts) → 14 vendor tabs (one per scope) → Lists (dropdown values) → Sources (all URLs used to seed).
A8: HOW TO USE
A9: Add a vendor | B9: Type in the next empty row of the right tab. Use the next Vendor ID (e.g., ENV-009). Dashboard updates automatically.
A10: Yellow columns | B10: Enter from direct vendor contact: Primary Contact Name/Title/Email/Phone, Last Contact Date, Next Action, Next Action Due.
A11: Dropdowns | B11: Qualification Status, Last RFx Stage, Financial Strength, Supply Chain Risk, Data Verified?. Edit options on the Lists tab only.
A12: Verify before use | B12: Set 'Data Verified?' to 'Yes - Verified' once HQ, contact and ownership are confirmed with the vendor.
A13: Overdue | B13: Next Action Due turns red when past today.
A15: QUALIFICATION STATUS (per CONTEXT.md process)
A16: Discovery | B16: Identified in market scan; no contact yet. All seeded vendors start here.
A17: Prequalified | B17: Passed prequalification (as part of or before RFI).
A18: Qualified | B18: Passed qualification (as part of RFP).
A19: AVL | B19: On Approved Vendor List; eligible for RFQ.
A20: On Hold | B20: Paused (capacity, pending M&A, info outstanding).
A21: Disqualified | B21: Failed a gate or excluded; record reason in Notes.
A23: ADDITIONAL TRACKED ITEMS (selected 2026-10-05)
A24: Financial Strength / Bankability | B24: Ownership/parent, financial notes (M&A, listings, scale), and a rating (Strong / Adequate / Weak / Not Assessed). Why: counterparty, warranty and lender-acceptance risk on long-lead, high-value scopes.
A25: Supply Chain / Origin Risk | B25: Manufacturing/cell origin or staff/delivery origin, plus a risk flag. Why: FEOC rules, tariffs and lead-time exposure, esp. BESS and transformers.
A27: SEEDED DATA — LIMITS AND RISKS
A28: Status | B28: Seeded by AI web research on 2026-10-05. Every seeded row is 'Discovery' and 'No - AI seeded'. Not confirmed market data.
A29: Contacts | B29: Only main phone numbers/contact pages published on official pages were entered. No individual contacts were added; blanks mean not confirmed.
A30: Financial Strength | B30: All set to 'Not Assessed'. AI did not rate financial strength; ratings need statements, credit reports or lender acceptance.
A31: FEOC Review flag | B31: Set where sources mention Chinese-parent or China-origin cell exposure. It is a review flag, not a legal determination; confirm with counsel/tax advisor.
A32: Pending M&A (as of 2026-10-05) | B32: Bowman (Bernhard Capital, pending), Jensen Hughes (New Mountain Capital, expected Q4 2026), PCI Energy Solutions (Mitsubishi Electric, pending), Enverus (Blackstone; close not confirmed). Re-check before RFx.
A33: Common ownership | B33: WSP owns POWER Engineers and TRC; MasTec owns former IEA/Wanzek/White. Treat as related bidders when assessing competition.
A34: Thin markets | B34: HV Breakers: ~5 suppliers with current 345 kV offerings (HD Hyundai listed as watchlist). Expect long lead times; engage early.
A35: Duplicates | B35: Some firms sit on several tabs by design (one row per scope). Keep contact data consistent across tabs.
A36: Software scope | B36: Assumed: ERCOT QSE/bidding, BESS EMS/optimization, asset performance, market data. Adjust if procurement/ERP software was intended.
A38: Legend
A39: Enter from vendor | B39: Yellow fill = user-entered fields
A40: Vendor | B40: Column group band on vendor tabs
A41: HQ Location | B41: Column group band on vendor tabs
A42: Contact Information | B42: Column group band on vendor tabs
A43: Qualification | B43: Column group band on vendor tabs
A44: Financial Strength / Bankability | B44: Column group band on vendor tabs
A45: Supply Chain / Origin Risk | B45: Column group band on vendor tabs
A46: Tracking | B46: Column group band on vendor tabs

Sheet Dashboard
A1: Vendor Landscape — Dashboard
A2: All figures are live formulas over the vendor tabs.
A4: Vendor Tab | B4: Total | C4: Discovery | D4: Prequalified | E4: Qualified | F4: AVL | G4: On Hold | H4: Disqualified | I4: FEOC Review | J4: High SC Risk | K4: Fin. Not Assessed | L4: Overdue Actions | M4: Unverified
A5: Env Eng | B5: =COUNTA('Env Eng'!$B$5:$B$300) -> 8 | C5: =COUNTIF('Env Eng'!$P$5:$P$300,"Discovery") -> 8 | D5: =COUNTIF('Env Eng'!$P$5:$P$300,"Prequalified") -> 0 | E5: =COUNTIF('Env Eng'!$P$5:$P$300,"Qualified") -> 0 | F5: =COUNTIF('Env Eng'!$P$5:$P$300,"AVL") -> 0 | G5: =COUNTIF('Env Eng'!$P$5:$P$300,"On Hold") -> 0 | H5: =COUNTIF('Env Eng'!$P$5:$P$300,"Disqualified") -> 0 | I5: =COUNTIF('Env Eng'!$W$5:$W$300,"FEOC Review") -> 0 | J5: =COUNTIF('Env Eng'!$W$5:$W$300,"High") -> 0 | K5: =COUNTIF('Env Eng'!$T$5:$T$300,"Not Assessed") -> 8 | L5: =COUNTIFS('Env Eng'!$Z$5:$Z$300,"<"&TODAY(),'Env Eng'!$Z$5:$Z$300,"<>") -> 0 | M5: =COUNTIF('Env Eng'!$AB$5:$AB$300,"No - AI seeded") -> 8
A6: Civil Eng | B6: =COUNTA('Civil Eng'!$B$5:$B$300) -> 7 | C6: =COUNTIF('Civil Eng'!$P$5:$P$300,"Discovery") -> 7 | D6: =COUNTIF('Civil Eng'!$P$5:$P$300,"Prequalified") -> 0 | E6: =COUNTIF('Civil Eng'!$P$5:$P$300,"Qualified") -> 0 | F6: =COUNTIF('Civil Eng'!$P$5:$P$300,"AVL") -> 0 | G6: =COUNTIF('Civil Eng'!$P$5:$P$300,"On Hold") -> 0 | H6: =COUNTIF('Civil Eng'!$P$5:$P$300,"Disqualified") -> 0 | I6: =COUNTIF('Civil Eng'!$W$5:$W$300,"FEOC Review") -> 0 | J6: =COUNTIF('Civil Eng'!$W$5:$W$300,"High") -> 0 | K6: =COUNTIF('Civil Eng'!$T$5:$T$300,"Not Assessed") -> 7 | L6: =COUNTIFS('Civil Eng'!$Z$5:$Z$300,"<"&TODAY(),'Civil Eng'!$Z$5:$Z$300,"<>") -> 0 | M6: =COUNTIF('Civil Eng'!$AB$5:$AB$300,"No - AI seeded") -> 7
A7: Structural Eng | B7: =COUNTA('Structural Eng'!$B$5:$B$300) -> 6 | C7: =COUNTIF('Structural Eng'!$P$5:$P$300,"Discovery") -> 6 | D7: =COUNTIF('Structural Eng'!$P$5:$P$300,"Prequalified") -> 0 | E7: =COUNTIF('Structural Eng'!$P$5:$P$300,"Qualified") -> 0 | F7: =COUNTIF('Structural Eng'!$P$5:$P$300,"AVL") -> 0 | G7: =COUNTIF('Structural Eng'!$P$5:$P$300,"On Hold") -> 0 | H7: =COUNTIF('Structural Eng'!$P$5:$P$300,"Disqualified") -> 0 | I7: =COUNTIF('Structural Eng'!$W$5:$W$300,"FEOC Review") -> 0 | J7: =COUNTIF('Structural Eng'!$W$5:$W$300,"High") -> 0 | K7: =COUNTIF('Structural Eng'!$T$5:$T$300,"Not Assessed") -> 6 | L7: =COUNTIFS('Structural Eng'!$Z$5:$Z$300,"<"&TODAY(),'Structural Eng'!$Z$5:$Z$300,"<>") -> 0 | M7: =COUNTIF('Structural Eng'!$AB$5:$AB$300,"No - AI seeded") -> 6
A8: Electrical Eng | B8: =COUNTA('Electrical Eng'!$B$5:$B$300) -> 8 | C8: =COUNTIF('Electrical Eng'!$P$5:$P$300,"Discovery") -> 8 | D8: =COUNTIF('Electrical Eng'!$P$5:$P$300,"Prequalified") -> 0 | E8: =COUNTIF('Electrical Eng'!$P$5:$P$300,"Qualified") -> 0 | F8: =COUNTIF('Electrical Eng'!$P$5:$P$300,"AVL") -> 0 | G8: =COUNTIF('Electrical Eng'!$P$5:$P$300,"On Hold") -> 0 | H8: =COUNTIF('Electrical Eng'!$P$5:$P$300,"Disqualified") -> 0 | I8: =COUNTIF('Electrical Eng'!$W$5:$W$300,"FEOC Review") -> 0 | J8: =COUNTIF('Electrical Eng'!$W$5:$W$300,"High") -> 0 | K8: =COUNTIF('Electrical Eng'!$T$5:$T$300,"Not Assessed") -> 8 | L8: =COUNTIFS('Electrical Eng'!$Z$5:$Z$300,"<"&TODAY(),'Electrical Eng'!$Z$5:$Z$300,"<>") -> 0 | M8: =COUNTIF('Electrical Eng'!$AB$5:$AB$300,"No - AI seeded") -> 8
A9: Fire Eng | B9: =COUNTA('Fire Eng'!$B$5:$B$300) -> 7 | C9: =COUNTIF('Fire Eng'!$P$5:$P$300,"Discovery") -> 7 | D9: =COUNTIF('Fire Eng'!$P$5:$P$300,"Prequalified") -> 0 | E9: =COUNTIF('Fire Eng'!$P$5:$P$300,"Qualified") -> 0 | F9: =COUNTIF('Fire Eng'!$P$5:$P$300,"AVL") -> 0 | G9: =COUNTIF('Fire Eng'!$P$5:$P$300,"On Hold") -> 0 | H9: =COUNTIF('Fire Eng'!$P$5:$P$300,"Disqualified") -> 0 | I9: =COUNTIF('Fire Eng'!$W$5:$W$300,"FEOC Review") -> 0 | J9: =COUNTIF('Fire Eng'!$W$5:$W$300,"High") -> 0 | K9: =COUNTIF('Fire Eng'!$T$5:$T$300,"Not Assessed") -> 7 | L9: =COUNTIFS('Fire Eng'!$Z$5:$Z$300,"<"&TODAY(),'Fire Eng'!$Z$5:$Z$300,"<>") -> 0 | M9: =COUNTIF('Fire Eng'!$AB$5:$AB$300,"No - AI seeded") -> 7
A10: Owners Eng | B10: =COUNTA('Owners Eng'!$B$5:$B$300) -> 7 | C10: =COUNTIF('Owners Eng'!$P$5:$P$300,"Discovery") -> 7 | D10: =COUNTIF('Owners Eng'!$P$5:$P$300,"Prequalified") -> 0 | E10: =COUNTIF('Owners Eng'!$P$5:$P$300,"Qualified") -> 0 | F10: =COUNTIF('Owners Eng'!$P$5:$P$300,"AVL") -> 0 | G10: =COUNTIF('Owners Eng'!$P$5:$P$300,"On Hold") -> 0 | H10: =COUNTIF('Owners Eng'!$P$5:$P$300,"Disqualified") -> 0 | I10: =COUNTIF('Owners Eng'!$W$5:$W$300,"FEOC Review") -> 0 | J10: =COUNTIF('Owners Eng'!$W$5:$W$300,"High") -> 0 | K10: =COUNTIF('Owners Eng'!$T$5:$T$300,"Not Assessed") -> 7 | L10: =COUNTIFS('Owners Eng'!$Z$5:$Z$300,"<"&TODAY(),'Owners Eng'!$Z$5:$Z$300,"<>") -> 0 | M10: =COUNTIF('Owners Eng'!$AB$5:$AB$300,"No - AI seeded") -> 7
A11: Eng of Record | B11: =COUNTA('Eng of Record'!$B$5:$B$300) -> 7 | C11: =COUNTIF('Eng of Record'!$P$5:$P$300,"Discovery") -> 7 | D11: =COUNTIF('Eng of Record'!$P$5:$P$300,"Prequalified") -> 0 | E11: =COUNTIF('Eng of Record'!$P$5:$P$300,"Qualified") -> 0 | F11: =COUNTIF('Eng of Record'!$P$5:$P$300,"AVL") -> 0 | G11: =COUNTIF('Eng of Record'!$P$5:$P$300,"On Hold") -> 0 | H11: =COUNTIF('Eng of Record'!$P$5:$P$300,"Disqualified") -> 0 | I11: =COUNTIF('Eng of Record'!$W$5:$W$300,"FEOC Review") -> 0 | J11: =COUNTIF('Eng of Record'!$W$5:$W$300,"High") -> 0 | K11: =COUNTIF('Eng of Record'!$T$5:$T$300,"Not Assessed") -> 7 | L11: =COUNTIFS('Eng of Record'!$Z$5:$Z$300,"<"&TODAY(),'Eng of Record'!$Z$5:$Z$300,"<>") -> 0 | M11: =COUNTIF('Eng of Record'!$AB$5:$AB$300,"No - AI seeded") -> 7
A12: Independent Eng | B12: =COUNTA('Independent Eng'!$B$5:$B$300) -> 6 | C12: =COUNTIF('Independent Eng'!$P$5:$P$300,"Discovery") -> 6 | D12: =COUNTIF('Independent Eng'!$P$5:$P$300,"Prequalified") -> 0 | E12: =COUNTIF('Independent Eng'!$P$5:$P$300,"Qualified") -> 0 | F12: =COUNTIF('Independent Eng'!$P$5:$P$300,"AVL") -> 0 | G12: =COUNTIF('Independent Eng'!$P$5:$P$300,"On Hold") -> 0 | H12: =COUNTIF('Independent Eng'!$P$5:$P$300,"Disqualified") -> 0 | I12: =COUNTIF('Independent Eng'!$W$5:$W$300,"FEOC Review") -> 0 | J12: =COUNTIF('Independent Eng'!$W$5:$W$300,"High") -> 0 | K12: =COUNTIF('Independent Eng'!$T$5:$T$300,"Not Assessed") -> 6 | L12: =COUNTIFS('Independent Eng'!$Z$5:$Z$300,"<"&TODAY(),'Independent Eng'!$Z$5:$Z$300,"<>") -> 0 | M12: =COUNTIF('Independent Eng'!$AB$5:$AB$300,"No - AI seeded") -> 6
A13: BESS Equipment | B13: =COUNTA('BESS Equipment'!$B$5:$B$300) -> 10 | C13: =COUNTIF('BESS Equipment'!$P$5:$P$300,"Discovery") -> 10 | D13: =COUNTIF('BESS Equipment'!$P$5:$P$300,"Prequalified") -> 0 | E13: =COUNTIF('BESS Equipment'!$P$5:$P$300,"Qualified") -> 0 | F13: =COUNTIF('BESS Equipment'!$P$5:$P$300,"AVL") -> 0 | G13: =COUNTIF('BESS Equipment'!$P$5:$P$300,"On Hold") -> 0 | H13: =COUNTIF('BESS Equipment'!$P$5:$P$300,"Disqualified") -> 0 | I13: =COUNTIF('BESS Equipment'!$W$5:$W$300,"FEOC Review") -> 9 | J13: =COUNTIF('BESS Equipment'!$W$5:$W$300,"High") -> 0 | K13: =COUNTIF('BESS Equipment'!$T$5:$T$300,"Not Assessed") -> 10 | L13: =COUNTIFS('BESS Equipment'!$Z$5:$Z$300,"<"&TODAY(),'BESS Equipment'!$Z$5:$Z$300,"<>") -> 0 | M13: =COUNTIF('BESS Equipment'!$AB$5:$AB$300,"No - AI seeded") -> 10
A14: MV Transformers | B14: =COUNTA('MV Transformers'!$B$5:$B$300) -> 10 | C14: =COUNTIF('MV Transformers'!$P$5:$P$300,"Discovery") -> 10 | D14: =COUNTIF('MV Transformers'!$P$5:$P$300,"Prequalified") -> 0 | E14: =COUNTIF('MV Transformers'!$P$5:$P$300,"Qualified") -> 0 | F14: =COUNTIF('MV Transformers'!$P$5:$P$300,"AVL") -> 0 | G14: =COUNTIF('MV Transformers'!$P$5:$P$300,"On Hold") -> 0 | H14: =COUNTIF('MV Transformers'!$P$5:$P$300,"Disqualified") -> 0 | I14: =COUNTIF('MV Transformers'!$W$5:$W$300,"FEOC Review") -> 0 | J14: =COUNTIF('MV Transformers'!$W$5:$W$300,"High") -> 0 | K14: =COUNTIF('MV Transformers'!$T$5:$T$300,"Not Assessed") -> 10 | L14: =COUNTIFS('MV Transformers'!$Z$5:$Z$300,"<"&TODAY(),'MV Transformers'!$Z$5:$Z$300,"<>") -> 0 | M14: =COUNTIF('MV Transformers'!$AB$5:$AB$300,"No - AI seeded") -> 10
A15: HV Breakers | B15: =COUNTA('HV Breakers'!$B$5:$B$300) -> 6 | C15: =COUNTIF('HV Breakers'!$P$5:$P$300,"Discovery") -> 6 | D15: =COUNTIF('HV Breakers'!$P$5:$P$300,"Prequalified") -> 0 | E15: =COUNTIF('HV Breakers'!$P$5:$P$300,"Qualified") -> 0 | F15: =COUNTIF('HV Breakers'!$P$5:$P$300,"AVL") -> 0 | G15: =COUNTIF('HV Breakers'!$P$5:$P$300,"On Hold") -> 0 | H15: =COUNTIF('HV Breakers'!$P$5:$P$300,"Disqualified") -> 0 | I15: =COUNTIF('HV Breakers'!$W$5:$W$300,"FEOC Review") -> 0 | J15: =COUNTIF('HV Breakers'!$W$5:$W$300,"High") -> 0 | K15: =COUNTIF('HV Breakers'!$T$5:$T$300,"Not Assessed") -> 6 | L15: =COUNTIFS('HV Breakers'!$Z$5:$Z$300,"<"&TODAY(),'HV Breakers'!$Z$5:$Z$300,"<>") -> 0 | M15: =COUNTIF('HV Breakers'!$AB$5:$AB$300,"No - AI seeded") -> 6
A16: MV Breakers | B16: =COUNTA('MV Breakers'!$B$5:$B$300) -> 7 | C16: =COUNTIF('MV Breakers'!$P$5:$P$300,"Discovery") -> 7 | D16: =COUNTIF('MV Breakers'!$P$5:$P$300,"Prequalified") -> 0 | E16: =COUNTIF('MV Breakers'!$P$5:$P$300,"Qualified") -> 0 | F16: =COUNTIF('MV Breakers'!$P$5:$P$300,"AVL") -> 0 | G16: =COUNTIF('MV Breakers'!$P$5:$P$300,"On Hold") -> 0 | H16: =COUNTIF('MV Breakers'!$P$5:$P$300,"Disqualified") -> 0 | I16: =COUNTIF('MV Breakers'!$W$5:$W$300,"FEOC Review") -> 0 | J16: =COUNTIF('MV Breakers'!$W$5:$W$300,"High") -> 0 | K16: =COUNTIF('MV Breakers'!$T$5:$T$300,"Not Assessed") -> 7 | L16: =COUNTIFS('MV Breakers'!$Z$5:$Z$300,"<"&TODAY(),'MV Breakers'!$Z$5:$Z$300,"<>") -> 0 | M16: =COUNTIF('MV Breakers'!$AB$5:$AB$300,"No - AI seeded") -> 7
A17: EPC | B17: =COUNTA(EPC!$B$5:$B$300) -> 8 | C17: =COUNTIF(EPC!$P$5:$P$300,"Discovery") -> 8 | D17: =COUNTIF(EPC!$P$5:$P$300,"Prequalified") -> 0 | E17: =COUNTIF(EPC!$P$5:$P$300,"Qualified") -> 0 | F17: =COUNTIF(EPC!$P$5:$P$300,"AVL") -> 0 | G17: =COUNTIF(EPC!$P$5:$P$300,"On Hold") -> 0 | H17: =COUNTIF(EPC!$P$5:$P$300,"Disqualified") -> 0 | I17: =COUNTIF(EPC!$W$5:$W$300,"FEOC Review") -> 0 | J17: =COUNTIF(EPC!$W$5:$W$300,"High") -> 0 | K17: =COUNTIF(EPC!$T$5:$T$300,"Not Assessed") -> 8 | L17: =COUNTIFS(EPC!$Z$5:$Z$300,"<"&TODAY(),EPC!$Z$5:$Z$300,"<>") -> 0 | M17: =COUNTIF(EPC!$AB$5:$AB$300,"No - AI seeded") -> 8
A18: Software | B18: =COUNTA(Software!$B$5:$B$300) -> 12 | C18: =COUNTIF(Software!$P$5:$P$300,"Discovery") -> 12 | D18: =COUNTIF(Software!$P$5:$P$300,"Prequalified") -> 0 | E18: =COUNTIF(Software!$P$5:$P$300,"Qualified") -> 0 | F18: =COUNTIF(Software!$P$5:$P$300,"AVL") -> 0 | G18: =COUNTIF(Software!$P$5:$P$300,"On Hold") -> 0 | H18: =COUNTIF(Software!$P$5:$P$300,"Disqualified") -> 0 | I18: =COUNTIF(Software!$W$5:$W$300,"FEOC Review") -> 0 | J18: =COUNTIF(Software!$W$5:$W$300,"High") -> 0 | K18: =COUNTIF(Software!$T$5:$T$300,"Not Assessed") -> 12 | L18: =COUNTIFS(Software!$Z$5:$Z$300,"<"&TODAY(),Software!$Z$5:$Z$300,"<>") -> 0 | M18: =COUNTIF(Software!$AB$5:$AB$300,"No - AI seeded") -> 12
A19: Total (vendor-tab entries) | B19: =SUM(B5:B18) -> 109 | C19: =SUM(C5:C18) -> 109 | D19: =SUM(D5:D18) -> 0 | E19: =SUM(E5:E18) -> 0 | F19: =SUM(F5:F18) -> 0 | G19: =SUM(G5:G18) -> 0 | H19: =SUM(H5:H18) -> 0 | I19: =SUM(I5:I18) -> 9 | ... M19: =SUM(M5:M18) -> 109
A20: Note: some firms appear on several tabs (e.g., Burns & McDonnell, Sargent & Lundy, DNV), so totals count tab entries, not unique companies.

Sheet Env Eng
A1: Environmental engineering consultants — Vendor Landscape
A2: Seeded 2026-10-05 from public sources (Discovery stage, unverified). Yellow columns = enter from vendor contact. Confirm all data before use; see Read Me.
A3: Vendor | D3: HQ Location | I3: Contact Information | P3: Qualification | S3: Financial Strength / Bankability | V3: Supply Chain / Origin Risk | X3: Tracking
A4: Vendor ID | B4: Vendor Name | C4: Environmental Services | D4: HQ City | E4: HQ State / Prov | F4: HQ Country | G4: US HQ (if foreign) | H4: Texas Presence | I4: Website | J4: Main Phone | K4: Contact Page | L4: Primary Contact Name | M4: Contact Title | N4: Contact Email | O4: Contact Phone | P4: Qualification Status | Q4: Status Date | R4: Last RFx Stage | S4: Ownership / Parent | T4: Financial Strength | U4: Financial / Bankability Notes | V4: Staff / Delivery Origin | W4: Supply Chain Risk | X4: Last Contact Date | Y4: Next Action | Z4: Next Action Due | AA4: Notes | AB4: Data Verified? | AC4: Primary Source
A5: ENV-001 | B5: ERM (Environmental Resources Management) | C5: Environmental, health, safety, risk and social consulting; permitting/impact assessment and sustainability services for energy projects | D5: London | F5: United Kingdom | I5: https://www.erm.com/ | K5: https://www.erm.com/contact-us/ | P5: Discovery | Q5: 46300 | R5: None | S5: PE-backed: KKR majority stake (acquired May 2021, ~US$2.7B valuation); ERM partners hold minority | T5: Not Assessed | U5: ~8,000 employees, 140+ offices in 40+ countries; revenue US$1.32B (2023); June 2024 agreed to acquire energy-transition advisory Energetics | V5: Global firm; US offices exist but Texas office locations not confirmed (locations page blocked) | W5: Not Assessed | AB5: No - AI seeded | AC5: https://en.wikipedia.org/wiki/ERM_(consultancy)
A6: ENV-002 | B6: Tetra Tech, Inc. | C6: Environmental consulting and engineering (water, environment, energy); permitting, site assessment, natural/cultural resources | D6: Pasadena | E6: CA | F6: USA | I6: https://www.tetratech.com/ | J6: +1 (626) 351-4664 | K6: https://www.tetratech.com/contact/ | P6: Discovery | Q6: 46300 | R6: None | S6: Public (NASDAQ: TTEK) | T6: Not Assessed | U6: ~28,000 employees (Oct 2024); 550 locations globally; acquired LS Technologies (Feb 2024) and Convergence Controls & Engineering (May 2024) | V6: US-based; site states offices in every US state (Texas cities not listed on fetched pages) | W6: Not Assessed | AB6: No - AI seeded | AC6: https://www.tetratech.com/contact/
A7: ENV-003 | B7: Stantec Inc. | C7: Environmental consulting and engineering; environmental permitting and studies for energy/infrastructure projects | D7: Edmonton | E7: AB | F7: Canada | H7: Austin; Dallas; Houston; San Antonio | I7: https://www.stantec.com/en | P7: Discovery | Q7: 46300 | R7: None | S7: Public (TSX/NYSE: STN) | T7: Not Assessed | U7: ~30,000 employees (2024); acquired Page (architecture, Aug 2025) | V7: Texas offices confirmed via stantec.com office pages (Houston 1100 Louisiana St; Barkers Landing; Dallas Main St; Austin Aldrich St/6th St; San Antonio) | W7: Not Assessed | AB7: No - AI seeded | AC7: https://en.wikipedia.org/wiki/Stantec
A8: ENV-004 | B8: WSP Global Inc. (WSP USA) | C8: Environmental, engineering and permitting consulting; power & energy platform (incl. POWER Engineers and TRC) | D8: Montreal | E8: QC | F8: Canada | H8: Austin; Corpus Christi; Dallas; El Paso; Fort Worth; Houston; San Antonio; Spring; Tyler; Victoria | I8: https://www.wsp.com/en-us | K8: https://www.wsp.com/en-us/contact-us | P8: Discovery | Q8: 46300 | R8: None | S8: Public (TSX: WSP) | T8: Not Assessed | U8: ~83,000 employees (Feb 2026); revenue C$16.17B (2024); acquired POWER Engineers (closed Oct 1 2024, US$1.78B), Ricardo (Jun 2025), TRC (closed Feb 24 2026, ~$3.3B); abandoned Arcadis bid Sep 2026 | V8: US operations led from New York (One Penn Plaza) per office listing | W8: Not Assessed | AB8: No - AI seeded | AC8: https://en.wikipedia.org/wiki/WSP_Global
A9: ENV-005 | B9: Terracon Consultants, Inc. | C9: Environmental site assessment (Phase I/II ESA), geotechnical, materials testing and facilities consulting | D9: Olathe | E9: KS | F9: USA | H9: Austin; Houston; San Antonio; Frisco; DFW Metro | I9: https://www.terracon.com/ | J9: (800) 593-7777 | K9: https://www.terracon.com/contact/ | P9: Discovery | Q9: 46300 | R9: None | S9: Private, 100% employee-owned | T9: Not Assessed | U9: 6,000+ employees, 200+ locations; ENR Top 500 Design Firms #18 (2024); founded 1965 | V9: US-based staff; national office network | W9: Not Assessed | AB9: No - AI seeded | AC9: https://www.terracon.com/contact/
A10: ENV-006 | B10: SWCA Environmental Consultants | C10: Environmental planning/permitting, natural & cultural resources, renewable energy environmental services | D10: Phoenix | E10: AZ | F10: USA | H10: Arlington; Austin; Houston; San Antonio | I10: https://www.swca.com/ | J10: 602-274-3831 | K10: https://www.swca.com/contact/ | P10: Discovery | Q10: 46300 | R10: None | S10: Private, 100% employee-owned (ESOP since 2000) | T10: Not Assessed | U10: 1,700+ employees, 46 US offices; ENR Top 500 Design Firms #93 (2026); founded 1980 in Flagstaff | V10: US-based staff; Phoenix office is corporate HQ and focuses on renewable energy, environmental planning, cultural resources | W10: Not Assessed | AB10: No - AI seeded | AC10: https://www.swca.com/contact
A11: ENV-007 | B11: Westwood Professional Services | C11: Renewable/BESS development support incl. environmental permitting, survey, and design of standalone and hybrid battery storage | D11: Plano | E11: TX | F11: USA | H11: Plano (HQ); Austin; Celina; Dallas; Farmers Branch; Fort Worth; Frisco; Houston; San Antonio; Victoria | I11: https://westwoodps.com/ | J11: 214-473-4640 (HQ); 1-888-937-5150 (toll-free) | K11: https://westwoodps.com/contact-us | P11: Discovery | Q11: 46300 | R11: None | S11: PE-backed: Blackstone (Energy Transition Partners) majority since Aug 2024; management/employees retain minority (prior owner Endurance Partners) | T11: Not Assessed | U11: 1,600+ employees (2024); HQ relocated from Minneapolis to Plano, TX late 2023; founded 1971 | V11: US-based staff; strong Texas presence | W11: Not Assessed | AB11: No - AI seeded | AC11: https://westwoodps.com/about-us/offices
A12: ENV-008 | B12: HDR, Inc. | C12: Engineering, environmental and architecture consulting incl. environmental planning for infrastructure/energy | D12: Omaha | E12: NE | F12: USA | H12: Austin; Dallas; Houston; San Antonio; El Paso; Spring Branch | I12: https://www.hdrinc.com/ | J12: (402) 399-1000 | K12: https://www.hdrinc.com/contact-us | P12: Discovery | Q12: 46300 | R12: None | S12: Private, employee-owned | T12: Not Assessed | U12: 12,000+ employees; revenue $2.8B (2022); ENR #6 design firm (2023) | V12: US-based staff | W12: Not Assessed | AB12: No - AI seeded | AC12: https://www.hdrinc.com/contact-us

Sheet Civil Eng
A1: Civil engineering consultants — Vendor Landscape
A2: Seeded 2026-10-05 from public sources (Discovery stage, unverified). Yellow columns = enter from vendor contact. Confirm all data before use; see Read Me.
A3: Vendor | D3: HQ Location | I3: Contact Information | P3: Qualification | S3: Financial Strength / Bankability | V3: Supply Chain / Origin Risk | X3: Tracking
A4: Vendor ID | B4: Vendor Name | C4: Civil Services | D4: HQ City | E4: HQ State / Prov | F4: HQ Country | G4: US HQ (if foreign) | H4: Texas Presence | I4: Website | J4: Main Phone | K4: Contact Page | L4: Primary Contact Name | M4: Contact Title | N4: Contact Email | O4: Contact Phone | P4: Qualification Status | Q4: Status Date | R4: Last RFx Stage | S4: Ownership / Parent | T4: Financial Strength | U4: Financial / Bankability Notes | V4: Staff / Delivery Origin | W4: Supply Chain Risk | X4: Last Contact Date | Y4: Next Action | Z4: Next Action Due | AA4: Notes | AB4: Data Verified? | AC4: Primary Source
A5: CIV-001 | B5: Kimley-Horn and Associates, Inc. | C5: Site civil, grading/drainage, roads and planning/design; energy and infrastructure site development | D5: Raleigh | E5: NC | F5: USA | H5: Austin; Bryan/College Station; Celina; Childress; Dallas; Denton; Fort Worth; Frisco; Georgetown; Houston; Irving; Lubbock; McKinney; Pearland; Richardson; San Antonio; San Marcos; Sherman; Terrell; The Woodlands; Tyler; Weatherford | I5: https://www.kimley-horn.com/ | K5: https://www.kimley-horn.com/contact/ | P5: Discovery | Q5: 46300 | R5: None | S5: Private | T5: Not Assessed | U5: 11,000+ employees (2026); revenue $2.8B (2025); ENR Top 500 Design Firms #8 (2025) | V5: US-based staff; 170+ US locations | W5: Not Assessed | AB5: No - AI seeded | AC5: https://en.wikipedia.org/wiki/Kimley-Horn
A6: CIV-002 | B6: Westwood Professional Services | C6: Civil/site design, survey, and permitting for utility-scale solar, wind and BESS; power delivery | D6: Plano | E6: TX | F6: USA | H6: Plano (HQ); Austin; Celina; Dallas; Farmers Branch; Fort Worth; Frisco; Houston; San Antonio; Victoria | I6: https://westwoodps.com/ | J6: 214-473-4640 (HQ); 1-888-937-5150 (toll-free) | K6: https://westwoodps.com/contact-us | P6: Discovery | Q6: 46300 | R6: None | S6: PE-backed: Blackstone majority since Aug 2024 | T6: Not Assessed | U6: 1,600+ employees (2024); HQ moved to Plano, TX late 2023 | V6: US-based staff | W6: Not Assessed | AB6: No - AI seeded | AC6: https://westwoodps.com/about-us/offices
A7: CIV-003 | B7: Halff Associates, Inc. | C7: Infrastructure consulting: site civil, drainage/water resources, survey, transportation | D7: Richardson | E7: TX | F7: USA | H7: Richardson (HQ); Austin; Brownsville; Corpus Christi; Dallas; Fort Worth; Frisco; Houston; Lubbock; McAllen; Midland; San Antonio; The Woodlands; Tyler | I7: https://www.halff.com/ | K7: https://www.halff.com/contact/ | P7: Discovery | Q7: 46300 | R7: None | S7: Private, employee-owned | T7: Not Assessed | U7: 30+ offices in AR, FL, LA, OK, TX; Nov 2024 announced HQ move to 2380 Performance Dr, Richardson (80,000 sf); founded ~1950 | V7: US-based staff; Texas-headquartered | W7: Not Assessed | AB7: No - AI seeded | AC7: https://www.halff.com/contact/
A8: CIV-004 | B8: Pape-Dawson Engineers | C8: Civil engineering, survey, permitting; substation/switchyard civil design (170+ substations) and wind/solar civil | D8: San Antonio | E8: TX | F8: USA | H8: San Antonio (HQ); Amarillo; Austin; Corpus Christi; Dallas; Fort Worth; Houston; Longview; Lufkin; McKinney; Nacogdoches; New Braunfels; The Woodlands; Tyler | I8: https://www.pape-dawson.com/ | J8: 210-375-9000 | K8: https://www.pape-dawson.com/contact | P8: Discovery | Q8: 46300 | R8: None | S8: Private; Dawson family/management majority with growth capital from Palm Beach Capital (Apr 2023) | T8: Not Assessed | U8: Serial acquirer (e.g., BHC, KSA Engineers, Poulos & Bennett, GradyMinor); offices in TX, FL, GA, TN, KS, OK, LA, AL, AZ, KY | V8: US-based staff; Texas-headquartered | W8: Not Assessed | AB8: No - AI seeded | AC8: https://www.pape-dawson.com/contact
A9: CIV-005 | B9: Bowman Consulting Group Ltd. | C9: Infrastructure design, civil engineering, survey, environmental; energy design incl. battery storage | D9: Reston | E9: VA | F9: USA | H9: Austin; Arlington; Dallas (Plano); Houston; Marshall; Midland; San Antonio; San Marcos; Waco | I9: https://bowman.com/ | J9: (703) 464-1000 | K9: https://bowman.com/contact | P9: Discovery | Q9: 46300 | R9: None | S9: Public (NASDAQ: BWMN) - pending take-private by Bernhard Capital Partners | T9: Not Assessed | U9: 2,500+ employees; Aug 10 2026 agreed to be acquired by Bernhard Capital Partners at $43.00/sh (~$1.0B EV), expected close Q4 2026/Q1 2027; 42 acquisitions since 2021 IPO | V9: US-based staff; offices in 34+ states | W9: Not Assessed | AB9: No - AI seeded | AC9: https://investors.bowman.com/
A10: CIV-006 | B10: Terracon Consultants, Inc. | C10: Geotechnical engineering, materials testing and construction QA for site/foundation design | D10: Olathe | E10: KS | F10: USA | H10: Austin; Houston; San Antonio; Frisco; DFW Metro | I10: https://www.terracon.com/ | J10: (800) 593-7777 | K10: https://www.terracon.com/contact/ | P10: Discovery | Q10: 46300 | R10: None | S10: Private, 100% employee-owned | T10: Not Assessed | U10: 6,000+ employees, 200+ locations; ENR #18 (2024) | V10: US-based staff | W10: Not Assessed | AB10: No - AI seeded | AC10: https://www.terracon.com/contact/
A11: CIV-007 | B11: Burns & McDonnell | C11: Engineering/EPC incl. site civil for power generation, substations and transmission | D11: Kansas City | E11: MO | F11: USA | H11: Amarillo; Austin; Dallas-Fort Worth; Houston; Pearland; San Antonio | I11: https://www.burnsmcd.com/ | K11: https://info.burnsmcd.com/contact-us | P11: Discovery | Q11: 46300 | R11: None | S11: Private, 100% employee-owned (ESOP) | T11: Not Assessed | U11: 13,500+ employees (2023); revenue US$6.9B (2023); ENR Top 500 #7; 75+ offices | V11: US-based staff; Houston office 1700 West Loop South | W11: Not Assessed | AB11: No - AI seeded | AC11: https://en.wikipedia.org/wiki/Burns_%26_McDonnell

Sheet Structural Eng
A1: Structural engineering consultants — Vendor Landscape
A2: Seeded 2026-10-05 from public sources (Discovery stage, unverified). Yellow columns = enter from vendor contact. Confirm all data before use; see Read Me.
A3: Vendor | D3: HQ Location | I3: Contact Information | P3: Qualification | S3: Financial Strength / Bankability | V3: Supply Chain / Origin Risk | X3: Tracking
A4: Vendor ID | B4: Vendor Name | C4: Structural Services | D4: HQ City | E4: HQ State / Prov | F4: HQ Country | G4: US HQ (if foreign) | H4: Texas Presence | I4: Website | J4: Main Phone | K4: Contact Page | L4: Primary Contact Name | M4: Contact Title | N4: Contact Email | O4: Contact Phone | P4: Qualification Status | Q4: Status Date | R4: Last RFx Stage | S4: Ownership / Parent | T4: Financial Strength | U4: Financial / Bankability Notes | V4: Staff / Delivery Origin | W4: Supply Chain Risk | X4: Last Contact Date | Y4: Next Action | Z4: Next Action Due | AA4: Notes | AB4: Data Verified? | AC4: Primary Source
A5: STR-001 | B5: Walter P Moore | C5: Structural and civil engineering, foundations, forensic engineering | D5: Houston | E5: TX | F5: USA | H5: Houston (HQ); Austin; Dallas; El Paso; Fort Worth; The Woodlands | I5: https://www.walterpmoore.com/ | J5: 800-364-7300 (general); 713-630-7300 (Houston HQ) | K5: https://www.walterpmoore.com/contact | P5: Discovery | Q5: 46300 | R5: None | S5: Private | T5: Not Assessed | U5: 1,250+ staff, 36 offices in 6 countries; founded 1931 | V5: US-based staff; Texas-headquartered; India office exists | W5: Not Assessed | AB5: No - AI seeded | AC5: https://www.walterpmoore.com/about
A6: STR-002 | B6: Sargent & Lundy | C6: Power engineering incl. structural design for generation, BESS, substations and transmission structures | D6: Chicago | E6: IL | F6: USA | H6: Houston | I6: https://www.sargentlundy.com/ | J6: (312) 269-2000 | K6: https://www.sargentlundy.com/contact-us | P6: Discovery | Q6: 46300 | R6: None | S6: Private, engineer-owned | T6: Not Assessed | U6: ~2,000+ employees; 30-40+ offices; founded 1891 | V6: US-based staff; international offices incl. India, UAE, Saudi Arabia, South Korea | W6: Not Assessed | AB6: No - AI seeded | AC6: https://www.sargentlundy.com/contact-us
A7: STR-003 | B7: Burns & McDonnell | C7: Structural/civil design for substations, equipment foundations and power plants (engineering/EPC) | D7: Kansas City | E7: MO | F7: USA | H7: Amarillo; Austin; Dallas-Fort Worth; Houston; Pearland; San Antonio | I7: https://www.burnsmcd.com/ | K7: https://info.burnsmcd.com/contact-us | P7: Discovery | Q7: 46300 | R7: None | S7: Private, 100% employee-owned (ESOP) | T7: Not Assessed | U7: 13,500+ employees (2023); revenue US$6.9B (2023); ENR #7 | V7: US-based staff | W7: Not Assessed | AB7: No - AI seeded | AC7: https://en.wikipedia.org/wiki/Burns_%26_McDonnell
A8: STR-004 | B8: Black & Veatch | C8: Engineering/EPC for power generation, power delivery and substations incl. structural design | D8: Overland Park | E8: KS | F8: USA | H8: Houston | I8: https://www.bv.com/ | J8: +1 913-458-2000 | K8: https://www.bv.com/contact-us | P8: Discovery | Q8: 46300 | R8: None | S8: Private, employee-owned | T8: Not Assessed | U8: ~13,000 employees (2024); revenue $4.735B (2023); 100+ offices; acquired Bird Electric Enterprises (2023) | V8: US-based staff with global offices | W8: Not Assessed | AB8: No - AI seeded | AC8: https://www.bv.com/contact-us
A9: STR-005 | B9: POWER Engineers (a WSP company) | C9: Power delivery engineering incl. substation and transmission structural/civil design; renewables & storage | D9: Hailey | E9: ID | F9: USA | H9: Houston; Tyler | I9: https://www.powereng.com/ | P9: Discovery | Q9: 46300 | R9: None | S9: Subsidiary of WSP Global (TSX: WSP); acquisition closed Oct 1 2024 (US$1.78B); previously employee-owned | T9: Not Assessed | U9: ~4,000 employees, 50 North American offices at acquisition; founded 1976 | V9: US-based staff; powereng.com not fetchable (robots), Texas offices from powereng.com press release titles | W9: Not Assessed | AB9: No - AI seeded | AC9: https://www.wsp.com/en-us/news/2024/wsp-completes-acquisition-of-power-engineers
A10: STR-006 | B10: Electrical Consultants, Inc. (ECI) | C10: Power delivery only: civil, structural, electrical, survey for substations, transmission (to 765 kV), renewables and battery storage | D10: Billings | E10: MT | F10: USA | I10: https://eciusa.com/ | P10: Discovery | Q10: 46300 | R10: None | T10: Not Assessed | U10: 900+ professionals, 33+ offices (per FL Public Power assn listing); acquired Relay Application Innovation (2019); subsidiary EPC Services Company (design-build) | V10: US-based staff; company website not fetchable (SSL error) - phone/contact not verified on official page | W10: Not Assessed | AB10: No - AI seeded | AC10: https://www.flpublicpower.com/associate-membership/electrical-consultants-inc

Sheet Electrical Eng
A1: Electrical engineering consultants — Vendor Landscape
A2: Seeded 2026-10-05 from public sources (Discovery stage, unverified). Yellow columns = enter from vendor contact. Confirm all data before use; see Read Me.
A3: Vendor | D3: HQ Location | I3: Contact Information | P3: Qualification | S3: Financial Strength / Bankability | V3: Supply Chain / Origin Risk | X3: Tracking
A4: Vendor ID | B4: Vendor Name | C4: Electrical Services | D4: HQ City | E4: HQ State / Prov | F4: HQ Country | G4: US HQ (if foreign) | H4: Texas Presence | I4: Website | J4: Main Phone | K4: Contact Page | L4: Primary Contact Name | M4: Contact Title | N4: Contact Email | O4: Contact Phone | P4: Qualification Status | Q4: Status Date | R4: Last RFx Stage | S4: Ownership / Parent | T4: Financial Strength | U4: Financial / Bankability Notes | V4: Staff / Delivery Origin | W4: Supply Chain Risk | X4: Last Contact Date | Y4: Next Action | Z4: Next Action Due | AA4: Notes | AB4: Data Verified? | AC4: Primary Source
A5: ELE-001 | B5: POWER Engineers (a WSP company) | C5: Substation, transmission and interconnection engineering; renewables & storage power delivery | D5: Hailey | E5: ID | F5: USA | H5: Houston; Tyler | I5: https://www.powereng.com/ | P5: Discovery | Q5: 46300 | R5: None | S5: Subsidiary of WSP Global (TSX: WSP) since Oct 1 2024 | T5: Not Assessed | U5: ~4,000 employees, 50 offices at acquisition (US$1.78B); WSP also closed TRC acquisition Feb 2026 | V5: US-based staff | W5: Not Assessed | AB5: No - AI seeded | AC5: https://www.wsp.com/en-us/news/2024/wsp-completes-acquisition-of-power-engineers
A6: ELE-002 | B6: Burns & McDonnell | C6: Substation/transmission design and EPC, interconnection and power generation electrical engineering | D6: Kansas City | E6: MO | F6: USA | H6: Amarillo; Austin; Dallas-Fort Worth; Houston; Pearland; San Antonio | I6: https://www.burnsmcd.com/ | K6: https://info.burnsmcd.com/contact-us | P6: Discovery | Q6: 46300 | R6: None | S6: Private, 100% employee-owned (ESOP) | T6: Not Assessed | U6: 13,500+ employees (2023); revenue US$6.9B (2023); ENR #7; selected by CPS Energy for turnkey grid modernization program | V6: US-based staff | W6: Not Assessed | AB6: No - AI seeded | AC6: https://en.wikipedia.org/wiki/Burns_%26_McDonnell
A7: ELE-003 | B7: Sargent & Lundy | C7: Grid/substation/transmission engineering, renewables and BESS electrical design, owner's engineer/due diligence | D7: Chicago | E7: IL | F7: USA | H7: Houston | I7: https://www.sargentlundy.com/ | J7: (312) 269-2000 | K7: https://www.sargentlundy.com/contact-us | P7: Discovery | Q7: 46300 | R7: None | S7: Private, engineer-owned | T7: Not Assessed | U7: ~2,000+ employees; founded 1891 | V7: US-based staff; international offices incl. India | W7: Not Assessed | AB7: No - AI seeded | AC7: https://www.sargentlundy.com/contact-us
A8: ELE-004 | B8: Black & Veatch | C8: Power delivery (substation/transmission) engineering and EPC; generation and storage | D8: Overland Park | E8: KS | F8: USA | H8: Houston | I8: https://www.bv.com/ | J8: +1 913-458-2000 | K8: https://www.bv.com/contact-us | P8: Discovery | Q8: 46300 | R8: None | S8: Private, employee-owned | T8: Not Assessed | U8: ~13,000 employees (2024); revenue $4.735B (2023) | V8: US-based staff with global offices | W8: Not Assessed | AB8: No - AI seeded | AC8: https://www.bv.com/contact-us
A9: ELE-005 | B9: Electric Power Engineers, LLC (EPE) | C9: Grid analysis/interconnection studies, utility engineering, regulatory/compliance; renewables & storage | D9: Austin | E9: TX | F9: USA | H9: Austin (HQ) | I9: https://epeconsulting.com/ | J9: 512-382-6700 | K9: https://epeconsulting.com/contact | P9: Discovery | Q9: 46300 | R9: None | S9: PE-backed: Berkshire Partners strategic growth investment (Jan 7 2025); Lime Rock New Energy exited; CEO/COO remain significant investors | T9: Not Assessed | U9: Founded 1968; 100+ developer/generation/utility clients | V9: US HQ Austin; other offices in Champaign IL, Waterloo ON, Beirut (Lebanon), Panama City | W9: Not Assessed | AB9: No - AI seeded | AC9: https://epeconsulting.com/contact
A10: ELE-006 | B10: TRC Companies, Inc. (a member of WSP) | C10: Power & utilities engineering incl. substation, transmission and interconnection; environmental | D10: Windsor | E10: CT | F10: USA | H10: Houston | I10: https://www.trccompanies.com/ | J10: +1 (860) 298-9692 | K10: https://www.trccompanies.com/contact-us/ | P10: Discovery | Q10: 46300 | R10: None | S10: Subsidiary of WSP Global (TSX: WSP); acquisition closed Feb 24 2026 | T10: Not Assessed | U10: ~8,000 professionals; ENR Top 500 #17; deal ~$3.3B per Wikipedia | V10: US-based staff | W10: Not Assessed | AB10: No - AI seeded | AC10: https://www.trccompanies.com/contact-us/
A11: ELE-007 | B11: Leidos (Power Delivery / Energy) | C11: Substation design (4-765 kV), T&D lines, SCADA, system planning, NERC compliance for Texas utilities | D11: Reston | E11: VA | F11: USA | H11: Houston; Fort Worth (per Leidos careers postings); site cites design centers across Texas | I11: https://www.leidos.com/ | K11: https://www.leidos.com/contact-us | P11: Discovery | Q11: 46300 | R11: None | S11: Public (NYSE: LDOS) | T11: Not Assessed | U11: ~47,000 employees (2026); revenue $17.2B (2025); Jan 2026 agreed to acquire Entrust Solutions Group (utility engineering) for ~$2.4B; ENR #4 T&D design (2022) | V11: US-based staff | W11: Not Assessed | AB11: No - AI seeded | AC11: https://www.leidos.com/markets/energy/texas
A12: ELE-008 | B12: Electrical Consultants, Inc. (ECI) | C12: Power delivery engineering: substations, transmission to 765 kV, protection & control, renewables/BESS | D12: Billings | E12: MT | F12: USA | I12: https://eciusa.com/ | P12: Discovery | Q12: 46300 | R12: None | T12: Not Assessed | U12: 900+ professionals, 33+ offices (FL Public Power assn listing); acquired Relay Application Innovation (2019) | V12: US-based staff; official site not reachable for verification | W12: Not Assessed | AB12: No - AI seeded | AC12: https://www.flpublicpower.com/associate-membership/electrical-consultants-inc

Sheet Fire Eng
A1: Fire protection engineering consultants — Vendor Landscape
A2: Seeded 2026-10-05 from public sources (Discovery stage, unverified). Yellow columns = enter from vendor contact. Confirm all data before use; see Read Me.
A3: Vendor | D3: HQ Location | I3: Contact Information | P3: Qualification | S3: Financial Strength / Bankability | V3: Supply Chain / Origin Risk | X3: Tracking
A4: Vendor ID | B4: Vendor Name | C4: Fire / BESS Hazard Services | D4: HQ City | E4: HQ State / Prov | F4: HQ Country | G4: US HQ (if foreign) | H4: Texas Presence | I4: Website | J4: Main Phone | K4: Contact Page | L4: Primary Contact Name | M4: Contact Title | N4: Contact Email | O4: Contact Phone | P4: Qualification Status | Q4: Status Date | R4: Last RFx Stage | S4: Ownership / Parent | T4: Financial Strength | U4: Financial / Bankability Notes | V4: Staff / Delivery Origin | W4: Supply Chain Risk | X4: Last Contact Date | Y4: Next Action | Z4: Next Action Due | AA4: Notes | AB4: Data Verified? | AC4: Primary Source
A5: FIRE-001 | B5: Jensen Hughes | C5: Lithium-ion/BESS risk consulting: hazard mitigation, NFPA 855/UL 9540A expertise, explosion protection (CFD, deflagration venting), large-scale fire testing | D5: Columbia | E5: MD | F5: USA | I5: https://www.jensenhughes.com/ | K5: https://www.jensenhughes.com/contact-us | P5: Discovery | Q5: 46300 | R5: None | S5: PE-backed: Gryphon Investors; Aug 5 2026 definitive agreement for New Mountain Capital to acquire (close expected Q4 2026) | T5: Not Assessed | U5: ~2,000 employees, 110 offices; founded 1939 | V5: Global firm; Texas office not confirmed | W5: Not Assessed | AB5: No - AI seeded | AC5: https://www.jensenhughes.com/contact-us
A6: FIRE-002 | B6: ESRG (Energy Safety Response Group) | C6: Energy-storage-only safety: testing, permitting/project review, emergency response plans & first-responder training, incident response | I6: https://www.energyresponsegroup.com/ | J6: 1-833-SAFE-ESS | K6: https://www.energyresponsegroup.com/contact | P6: Discovery | Q6: 46300 | R6: None | T6: Not Assessed | V6: Team of fire-service veterans; HQ not stated on site | W6: Not Assessed | AB6: No - AI seeded | AC6: https://energyresponsegroup.com/
A7: FIRE-003 | B7: Fire & Risk Alliance | C7: BESS code consulting (NFPA 855/IFC), HMA, UL 9540A assessment, deflagration (NFPA 68/69) and heat-flux modeling, FMEA, ERP and responder training | D7: Rockville | E7: MD | F7: USA | I7: https://fireriskalliance.com/ | J7: (301) 658-3060 | K7: https://fireriskalliance.com/contact-us/ | P7: Discovery | Q7: 46300 | R7: None | T7: Not Assessed | V7: Single listed office (Rockville, MD); 24/7 availability | W7: Not Assessed | AB7: No - AI seeded | AC7: https://fireriskalliance.com/
A8: FIRE-004 | B8: Telgian Engineering & Consulting | C8: Fire protection engineering and code consulting; has published ESS fire-hazard guidance (BESS-specific services not detailed on site) | D8: Phoenix | E8: AZ | F8: USA | H8: Richardson (Dallas office) | I8: https://www.telgian.com/ | J8: 480.753.5444 | K8: https://www.telgian.com/contact/ | P8: Discovery | Q8: 46300 | R8: None | S8: Private (Telgian Holdings, Inc.) | T8: Not Assessed | V8: US-based staff; offices in Atlanta, Chicago, Dallas, Denver, Irvine, Phoenix, Seattle, Wilmington DE, plus Toronto and Mexico City | W8: Not Assessed | AB8: No - AI seeded | AC8: https://www.telgian.com/contact/
A9: FIRE-005 | B9: DNV | C9: Battery safety, risk analysis (QRA) and permitting support; energy storage technical due diligence and engineering review | D9: Høvik (Oslo) | F9: Norway | H9: Houston (North American HQ) | I9: https://www.dnv.com/ | K9: https://www.dnv.us/contact/ | P9: Discovery | Q9: 46300 | R9: None | S9: Owned by the independent Det Norske Veritas Foundation | T9: Not Assessed | U9: ~15,000 employees (2024); revenue NOK 31.6B (2023); 1,500+ US employees | V9: Global firm; North American HQ Houston, TX | W9: Not Assessed | AB9: No - AI seeded | AC9: https://en.wikipedia.org/wiki/DNV
A10: FIRE-006 | B10: UL Solutions Inc. | C10: UL 9540A testing, NFPA 855 documentation readiness review, fire/explosion hazard assessment, AHJ-focused technical support | D10: Northbrook | E10: IL | F10: USA | H10: Houston; Plano; Rollingwood (Austin area) | I10: https://www.ul.com/ | J10: +1.877.854.3577 (customer service) | K10: https://www.ul.com/contact-us | P10: Discovery | Q10: 46300 | R10: None | S10: Public (NYSE: ULS), IPO April 16 2024 | T10: Not Assessed | U10: IPO ~US$1.08B (Apr 2024); serves 80,000+ companies | V10: US-based labs incl. Plano, TX | W10: Not Assessed | AB10: No - AI seeded | AC10: https://www.ul.com/services/ess-safety-assessment-and-nfpa-compliance
A11: FIRE-007 | B11: Exponent, Inc. | C11: BESS safety & risk consulting: fire protection engineering, emergency response planning, root-cause failure analysis, testing | D11: Menlo Park | E11: CA | F11: USA | H11: Houston | I11: https://www.exponent.com/ | J11: (650) 326-9400 | P11: Discovery | Q11: 46300 | R11: None | S11: Public (NASDAQ: EXPO) | T11: Not Assessed | U11: 20 US offices + 5 overseas; founded 1967 as Failure Analysis Associates | V11: US-based staff; Menlo Park HQ has on-site labs | W11: Not Assessed | AB11: No - AI seeded | AC11: https://www.exponent.com/offices/menlo-park

Sheet Owners Eng
A1: Owner's engineer — Vendor Landscape
A2: Seeded 2026-10-05 from public sources (Discovery stage, unverified). Yellow columns = enter from vendor contact. Confirm all data before use; see Read Me.
A3: Vendor | D3: HQ Location | I3: Contact Information | P3: Qualification | S3: Financial Strength / Bankability | V3: Supply Chain / Origin Risk | X3: Tracking
A4: Vendor ID | B4: Vendor Name | C4: OE Services | D4: HQ City | E4: HQ State / Prov | F4: HQ Country | G4: US HQ (if foreign) | H4: Texas Presence | I4: Website | J4: Main Phone | K4: Contact Page | L4: Primary Contact Name | M4: Contact Title | N4: Contact Email | O4: Contact Phone | P4: Qualification Status | Q4: Status Date | R4: Last RFx Stage | S4: Ownership / Parent | T4: Financial Strength | U4: Financial / Bankability Notes | V4: Staff / Delivery Origin | W4: Supply Chain Risk | X4: Last Contact Date | Y4: Next Action | Z4: Next Action Due | AA4: Notes | AB4: Data Verified? | AC4: Primary Source
A5: OE-001 | B5: DNV | C5: Owner's engineering for energy storage: feasibility, dispatch modeling, RFP/tender support, design and procurement review, grid connection, warranty definition, FAT/SAT, construction PM, HSE | D5: Høvik | F5: Norway | H5: Houston (North America HQ); Austin; Dallas (per DNV job postings) | I5: https://www.dnv.com | J5: +1 281 396 1000 (DNV North America HQ, Houston) | K5: https://www.dnv.us/contact/ | P5: Discovery | Q5: 46300 | R5: None | S5: Private; owned by the independent foundation Stiftelsen Det Norske Veritas | T5: Not Assessed | U5: 2025 operating revenue NOK 35,291 million (+0.9% y/y); operates in 100+ countries | V5: US energy-storage OE/IE staff posted in Houston, Austin, Dallas, plus Oakland, San Diego, Seattle, Portland, Medford MA, Chalfont PA, New York | W5: Not Assessed | AB5: No - AI seeded | AC5: https://www.dnv.com/services/owner-s-engineering-for-energy-storage-63162
A6: OE-002 | B6: Enertis Applus+ | C6: Renewables and BESS technical advisory: design evaluation, site assessment, engineering, QA/QC, testing and optimization for developers, owners and financiers | D6: Madrid | F6: Spain | I6: https://enertisapplus.com | J6: +1 415 671 4000 (US offices, San Francisco / Raleigh) | K6: https://enertisapplus.com/contact/ | P6: Discovery | Q6: 46300 | R6: None | S6: Subsidiary of Applus+ (Applus Services S.A.), taken private June 2024 by Amber EquityCo (TDR Capital and I Squared Capital) | T6: Not Assessed | U6: Parent Applus+: 26,000+ employees in 70+ countries; TDR/I Squared takeover completed 14 Jun 2024 | V6: US offices in San Francisco, CA and Raleigh, NC; Madrid HQ; 15 offices globally | W6: Not Assessed | AB6: No - AI seeded | AC6: https://enertisapplus.com/
A7: OE-003 | B7: Black & Veatch | C7: BESS owner's engineer: EPC design review, construction monitoring, commissioning supervision, early operations oversight; firm reports 74 GWh supported as OE | D7: Overland Park | E7: KS | F7: USA | H7: Houston (Energy Corridor; second-largest B&V office); Dallas; Deer Park | I7: https://www.bv.com | J7: +1 913-458-2000 | K7: https://www.bv.com/contact-us | P7: Discovery | Q7: 46300 | R7: None | S7: Private; 100% employee-owned | T7: Not Assessed | U7: Revenue ~$4.7B (2023); ~13,000 employees (2024); ENR 2024 #13 design firm, #4 power design; acquired Bird Electric (Texas electrical contractor, ~600 staff) 2023 | V7: Houston office houses 300+ staff and is the regional hub for power and energy (May 2026) | W7: Not Assessed | AB7: No - AI seeded | AC7: https://new.bv.com/news/black-and-veatch-appointed-as-owners-engineer-for-eccles-battery-storage-project-in-scotland
A8: OE-004 | B8: Sargent & Lundy | C8: Owner's engineer for utility-scale solar + BESS: EPC RFP/specs, bid evaluation, contract negotiation support, review of LV/MV, collection, substation and transmission designs | D8: Chicago | E8: IL | F8: USA | H8: Fort Worth; Houston; Midland | I8: https://www.sargentlundy.com | J8: 312-269-2000 | K8: https://www.sargentlundy.com/contact-us | P8: Discovery | Q8: 46300 | R8: None | S8: Private; owned and managed by its employees (engineers) | T8: Not Assessed | U8: Founded 1891; 30+ offices; acquisitions include Summit Engineering Services and ARES Corp. Energy Services Division (2019) | W8: Not Assessed | AB8: No - AI seeded | AC8: https://www.sargentlundy.com/contact-us
A9: OE-005 | B9: Clean Energy Associates (Intertek CEA) | C9: Owner's engineer and technical due diligence; storage system QA, factory/production monitoring, supply-chain traceability for BESS and PV | E9: CO | F9: USA | I9: https://www.cea3.com | P9: Discovery | Q9: 46300 | R9: None | S9: Subsidiary of Intertek Group plc (LSE: ITRK); acquired 2022 | T9: Not Assessed | U9: Acquisition completed mid-2022 (price undisclosed); CEA had 150+ employees and GBP 21.7M revenue in 2021 | V9: Staff across North America, Europe and Asia; significant operations in China (factory QA) | W9: Not Assessed | AB9: No - AI seeded | AC9: https://www.cea3.com/
A10: OE-006 | B10: Kimley-Horn | C10: BESS consulting incl. owner's engineering, feasibility, siting/permitting, interconnection studies, and civil/structural/electrical design | D10: Raleigh | E10: NC | F10: USA | H10: Austin | I10: https://www.kimley-horn.com | K10: https://www.kimley-horn.com/contact/submit-a-service-inquiry/ | P10: Discovery | Q10: 46300 | R10: None | S10: Private; employee-owned | T10: Not Assessed | U10: Revenue US$2.8B (2025); 11,000+ employees; ENR Top 500 Design Firms #8 (2025) | W10: Not Assessed | AB10: No - AI seeded | AC10: https://www.kimley-horn.com/services/energy-consulting/battery-energy-storage-systems-consulting/
A11: OE-007 | B11: Natural Power | C11: Renewables-only consultant: owner's advisory, technology evaluation, field inspections and technical due diligence for standalone/co-located storage | D11: Castle Douglas | E11: Scotland | F11: UK | I11: https://www.naturalpower.com | J11: +1 (518) 308 0200 (Saratoga Springs, NY office) | K11: https://www.naturalpower.com/us/contact | P11: Discovery | Q11: 46300 | R11: None | S11: Private; independent (founded 1995) | T11: Not Assessed | U11: 400+ staff globally; 30+ NA IE projects (6+ GW) in 2025 | V11: US offices: Saratoga Springs NY, Seattle WA, Golden CO | W11: Not Assessed | AB11: No - AI seeded | AC11: https://www.naturalpower.com/us/sector/energy-storage

Sheet Eng of Record
A1: Engineer of record — Vendor Landscape
A2: Seeded 2026-10-05 from public sources (Discovery stage, unverified). Yellow columns = enter from vendor contact. Confirm all data before use; see Read Me.
A3: Vendor | D3: HQ Location | I3: Contact Information | P3: Qualification | S3: Financial Strength / Bankability | V3: Supply Chain / Origin Risk | X3: Tracking
A4: Vendor ID | B4: Vendor Name | C4: EOR Services | D4: HQ City | E4: HQ State / Prov | F4: HQ Country | G4: US HQ (if foreign) | H4: Texas Presence | I4: Website | J4: Main Phone | K4: Contact Page | L4: Primary Contact Name | M4: Contact Title | N4: Contact Email | O4: Contact Phone | P4: Qualification Status | Q4: Status Date | R4: Last RFx Stage | S4: Ownership / Parent | T4: Financial Strength | U4: Financial / Bankability Notes | V4: Staff / Delivery Origin | W4: Supply Chain Risk | X4: Last Contact Date | Y4: Next Action | Z4: Next Action Due | AA4: Notes | AB4: Data Verified? | AC4: Primary Source
A5: EOR-001 | B5: Burns & McDonnell | C5: In-house design engineering and EPC for BESS, substations and transmission; delivered Texas BESS EPC (e.g., RWE Texas Waves II, LGES/SER West Texas) | D5: Kansas City | E5: MO | F5: USA | H5: Amarillo; Austin; Dallas-Fort Worth; Houston; Pearland; San Antonio | I5: https://www.burnsmcd.com | J5: (816) 333-9400 | K5: https://info.burnsmcd.com/contact-us | P5: Discovery | Q5: 46300 | R5: None | S5: Private; 100% employee-owned | T5: Not Assessed | U5: 75+ offices worldwide; founded 1898 | W5: Not Assessed | AB5: No - AI seeded | AC5: https://www.burnsmcd.com/
A6: EOR-002 | B6: Sargent & Lundy | C6: Power engineering firm: electrical design for collection, substation and transmission; renewables and storage engineering | D6: Chicago | E6: IL | F6: USA | H6: Fort Worth; Houston; Midland | I6: https://www.sargentlundy.com | J6: 312-269-2000 | K6: https://www.sargentlundy.com/contact-us | P6: Discovery | Q6: 46300 | R6: None | S6: Private; owned and managed by its employees (engineers) | T6: Not Assessed | U6: Founded 1891; 30+ offices | W6: Not Assessed | AB6: No - AI seeded | AC6: https://www.sargentlundy.com/contact-us
A7: EOR-003 | B7: POWER Engineers (Member of WSP) | C7: Power delivery engineering: substation, transmission, renewables and storage design | D7: Hailey | E7: ID | F7: USA | I7: https://www.powereng.com | P7: Discovery | Q7: 46300 | R7: None | S7: Subsidiary of WSP Global Inc. (TSX: WSP) | T7: Not Assessed | U7: Acquired by WSP for US$1.78B, completed 1 Oct 2024; ~4,000 employees, ~50 US locations | V7: WSP substation job postings show Fort Worth and Spring, TX roles (unconfirmed as POWER offices) | W7: Not Assessed | AB7: No - AI seeded | AC7: https://www.wsp.com/en-gl/investors/press-releases/details/WSP-Completes-Acquisition--of-POWER-Engineers/2956467/2024
A8: EOR-004 | B8: Westwood Professional Services | C8: Design, permitting and optimization of standalone/hybrid BESS; substation and transmission line engineering; surveying | D8: Plano | E8: TX | F8: USA | H8: Plano (HQ); Austin; Celina; Dallas; Farmers Branch; Fort Worth; Frisco; Houston; San Antonio; Victoria | I8: https://www.westwoodps.com | J8: 1-888-937-5150 | K8: https://westwoodps.com/contact-us | P8: Discovery | Q8: 46300 | R8: None | S8: PE-backed; Blackstone Energy Transition Partners majority investment (Aug 2024), previously Endurance Partners | T8: Not Assessed | U8: 1,600+ employees (2024); acquired O'Dell Engineering (California) | V8: Texas-headquartered | W8: Not Assessed | AB8: No - AI seeded | AC8: https://www.westwoodps.com/
A9: EOR-005 | B9: Black & Veatch | C9: Engineering and EPC for BESS and HV substations; firm reports 8.9 GWh delivered as BESS EPC | D9: Overland Park | E9: KS | F9: USA | H9: Houston; Dallas; Deer Park | I9: https://www.bv.com | J9: +1 913-458-2000 | K9: https://www.bv.com/contact-us | P9: Discovery | Q9: 46300 | R9: None | S9: Private; 100% employee-owned | T9: Not Assessed | U9: Revenue ~$4.7B (2023); ~13,000 employees; ENR 2024 #4 power design | W9: Not Assessed | AB9: No - AI seeded | AC9: https://new.bv.com/news/black-and-veatch-appointed-as-owners-engineer-for-eccles-battery-storage-project-in-scotland
A10: EOR-006 | B10: Kimley-Horn | C10: Detailed civil, structural and electrical BESS design incl. plant, HV substation and transmission/interconnection design | D10: Raleigh | E10: NC | F10: USA | H10: Austin | I10: https://www.kimley-horn.com | K10: https://www.kimley-horn.com/contact/submit-a-service-inquiry/ | P10: Discovery | Q10: 46300 | R10: None | S10: Private; employee-owned | T10: Not Assessed | U10: Revenue US$2.8B (2025); 11,000+ employees; ENR Top 500 Design Firms #8 (2025) | W10: Not Assessed | AB10: No - AI seeded | AC10: https://www.kimley-horn.com/services/energy-consulting/battery-energy-storage-systems-consulting/
A11: EOR-007 | B11: Bowman Consulting Group | C11: Energy design and engineering incl. BESS, electric power and transmission; civil/survey | D11: Reston | E11: VA | F11: USA | H11: Austin; Arlington; Plano (Dallas); Houston (2); Marshall; Midland; San Antonio; San Marcos; Waco | I11: https://bowman.com | K11: https://bowman.com/contact/ | P11: Discovery | Q11: 46300 | R11: None | S11: Public (Nasdaq: BWMN) | T11: Not Assessed | U11: FY2025 gross contract revenue ~$490M; 2,300+ employees; ENR Top 500 #72; 7 acquisitions in 2025 (~$75.4M) incl. RPT Alliance (Houston, Dec 2025) | W11: Not Assessed | AB11: No - AI seeded | AC11: https://bowman.com/services/battery-energy-storage-systems

Sheet Independent Eng
A1: Independent engineer — Vendor Landscape
A2: Seeded 2026-10-05 from public sources (Discovery stage, unverified). Yellow columns = enter from vendor contact. Confirm all data before use; see Read Me.
A3: Vendor | D3: HQ Location | I3: Contact Information | P3: Qualification | S3: Financial Strength / Bankability | V3: Supply Chain / Origin Risk | X3: Tracking
A4: Vendor ID | B4: Vendor Name | C4: IE Services | D4: HQ City | E4: HQ State / Prov | F4: HQ Country | G4: US HQ (if foreign) | H4: Texas Presence | I4: Website | J4: Main Phone | K4: Contact Page | L4: Primary Contact Name | M4: Contact Title | N4: Contact Email | O4: Contact Phone | P4: Qualification Status | Q4: Status Date | R4: Last RFx Stage | S4: Ownership / Parent | T4: Financial Strength | U4: Financial / Bankability Notes | V4: Staff / Delivery Origin | W4: Supply Chain Risk | X4: Last Contact Date | Y4: Next Action | Z4: Next Action Due | AA4: Notes | AB4: Data Verified? | AC4: Primary Source
A5: IE-001 | B5: DNV | C5: Independent engineering and technical due diligence for BESS: vendor/design/safety review, performance validation, guarantee verification, bankability for investors/financiers | D5: Høvik | F5: Norway | H5: Houston (North America HQ); Austin; Dallas (per DNV job postings) | I5: https://www.dnv.com | J5: +1 281 396 1000 (DNV North America HQ, Houston) | K5: https://www.dnv.us/contact/ | P5: Discovery | Q5: 46300 | R5: None | S5: Private; owned by the independent foundation Stiftelsen Det Norske Veritas | T5: Not Assessed | U5: 2025 operating revenue NOK 35,291 million | V5: Energy Storage IE PM roles posted in Austin and Houston among other US cities | W5: Not Assessed | AB5: No - AI seeded | AC5: https://www.dnv.com/services/independent-engineering-and-technical-due-diligence-63108/
A6: IE-002 | B6: Enertis Applus+ | C6: Lender's IE for BESS: project-finance technical due diligence, design/grid/warranty review, MC/SC/FC milestone certification (e.g., 550 MW / 1,433 MWh Texas portfolio for Excelsior/Lydian) | D6: Madrid | F6: Spain | I6: https://enertisapplus.com | J6: +1 415 671 4000 (US offices) | K6: https://enertisapplus.com/contact/ | P6: Discovery | Q6: 46300 | R6: None | S6: Subsidiary of Applus+ (private since June 2024; TDR Capital and I Squared Capital) | T6: Not Assessed | U6: Parent Applus+: 26,000+ employees, 70+ countries | V6: US offices in San Francisco, CA and Raleigh, NC | W6: Not Assessed | AB6: No - AI seeded | AC6: https://informedinfrastructure.com/index.php/post/enertis-applus-delivers-independent-engineering-expertise-to-texas-bess-projects-for-excelsior-energy-capital
